Workbook

Sheet 主材报价模板 
A1: 主材报价明细表
A2: 客户名称： | E2: 建筑面积（㎡）： | G2: =[1]半包报价模板!G2 -> 130 | H2: 工程地址： | I2: =[1]半包报价模板!I2 -> 0
A3: 编号 | C3: 材料名称 | D3: 规格 | E3: 单位 | F3: 数量 | G3: 工 程 造 价 | I3: 品牌
G4: 单价 | H4: 金额
A5: 【一、瓷 砖】
A6: 1 | C6: 广东一线冠珠 | D6: 600*1200 | E6: M2 | F6: =[1]半包报价模板!F33*1.15 -> 57.5 | G6: 105 | H6: =F6*G6 -> 6037.5 | I6: 冠珠柔/亮光砖 | J6: 65
A7: 2 | C7: 广东一线冠珠 | D7: 750*1500 | E7: M2 | F7: =[1]半包报价模板!F34*1.15 -> 0 | G7: 113 | H7: =F7*G7 -> 0 | I7: 冠珠柔/亮光砖 | J7: 70
A8: 3 | C8: 广东一线冠珠 | D8: 600*1200 | E8: M2 | F8: =[1]半包报价模板!F35*1.15 -> 0 | G8: 153 | H8: =F8*G8 -> 0 | I8: 冠珠莱姆石质感砖 | J8: 95
A9: 4 | C9: 广东一线冠珠 | D9: 750*1500 | E9: M2 | F9: =[1]半包报价模板!F36*1.15 -> 0 | G9: 170 | H9: =F9*G9 -> 0 | I9: 冠珠莱姆石质感砖 | J9: 105
A10: 5 | C10: KT木纹板 | D10: 600*1200 | E10: M2 | F10: 0 | G10: 105 | H10: =F10*G10 -> 0 | I10: KT木纹板 | J10: 65
A11: 6 | C11: KT木纹板（阿童木微模质感面） | D11: 600*1200 | E11: M2 | F11: 0 | G11: 138 | H11: =F11*G11 -> 0 | I11: KT木纹板（阿童木微模质感面） | J11: 87.5
A12: 7 | C12: KT南美橡木（微模质感面） | D12: 200*1200 | E12: M2 | F12: =[1]半包报价模板!F258*1.15 -> 0 | G12: 113 | H12: =F12*G12 -> 0 | I12: KT南美橡木（微模质感面） | J12: 70
A13: 8 | C13: 广东一线欧文莱 | D13: 600*1200 | E13: M2 | F13: 0 | G13: 190 | H13: =F13*G13 -> 0 | I13: 广东一线欧文莱 | J13: 118
A14: 9 | C14: 广东一线欧文莱 | D14: 750*1500 | E14: M2 | F14: 0 | G14: 208 | H14: =F14*G14 -> 0 | I14: 广东一线欧文莱 | J14: 128
A15: 10 | C15: 广东一线欧文莱 | D15: 900*1800 | E15: M2 | F15: 0 | G15: 367 | H15: =F15*G15 -> 0 | I15: 广东一线欧文莱 | J15: 228
A16: 11 | C16: 古堡砖 | D16: 多规格 | E16: M2 | F16: 0 | G16: 230 | H16: =F16*G16 -> 0 | I16: 土豆/印象 | J16: 145
A17: 12 | C17: 德祥筑家定制砖 | D17: 多规格 | E17: M2 | F17: 0 | G17: 238 | H17: =F17*G17 -> 0 | I17: 德祥筑家 | J17: 158
A18: 13 | C18: 定制小砖 | D18: 700*200/750*300/120*120 | E18: M2 | F18: 0 | G18: 280 | H18: =F18*G18 -> 0 | I18: 定制小砖 | J18: 190
A19: 14 | C19: 广东一线HBI | D19: 600*1200 | E19: M2 | F19: 0 | G19: 113 | H19: =F19*G19 -> 0 | I19: 广东一线HBI瓷砖（柔/亮面） | J19: 70
A20: 15 | C20: 广东一线HBI | D20: 750*1500 | E20: M2 | F20: 0 | G20: 120 | H20: =F20*G20 -> 0 | I20: 广东一线HBI瓷砖（柔/亮面） | J20: 75
A21: 16 | C21: 广东一线HBI | D21: 750*1500 | E21: M2 | F21: 0 | G21: 162 | H21: =F21*G21 -> 0 | I21: 广东一线HBI瓷砖（凹凸面） | J21: 100
A22: 17 | C22: 广东一线HBI | D22: 900*1800 | E22: M2 | F22: 0 | G22: 218 | H22: =F22*G22 -> 0 | I22: 广东一线HBI瓷砖 | J22: 135
H23: =SUM(H6:H22) -> 6037.5
A24: 【二、美 缝】
A25: 1 | C25: 美缝 | E25: M2 | F25: 0 | G25: 25 | H25: =F25*G25 -> 0 | I25: 梵聚匠/汉高百得 | J25: 16
A26: 2 | C26: 打胶收口 | E26: M2 | F26: 125 | G26: 10 | H26: =F26*G26 -> 1250 | I26: 瓦克（外框面积计算） | J26: 7
A27: 3 | C27: 小砖环氧彩砂 | E27: M2 | F27: 1 | G27: 180 | H27: =F27*G27 -> 180 | I27: 梵聚匠/汉高百得（规格10*100/100/200）压缝工艺（调色增加500元一个色） | J27: 100
A28: 4 | C28: 马贝环氧彩砂 | E28: 米 | F28: 1 | G28: 20 | H28: =F28*G28 -> 20 | I28: 马贝环氧彩砂（平缝工艺） | J28: 12
A29: 小计： | H29: =SUM(H25:H28) -> 1450
A30: 【三、木 地 板】
A31: 1 | C31: 木地板 | E31: M2 | F31: 0 | G31: 218 | H31: =F31*G31 -> 0 | I31: 根据款式每款价格都不一样
A32: 2 | C32: 木龙骨 | E32: M2 | F32: 0 | G32: 80 | H32: =F32*G32 -> 0 | I32: 木龙骨基层找平，间距30CM，门框位置加密 | J32: 50
A33: 3 | C33: 饰面木质踢脚线 | E33: M | F33: 0 | G33: 38 | H33: =F33*G33 -> 0 | I33: 成品木质踢脚线（无盯眼安装） | J33: 25
A34: 4 | C34: 烤漆踢脚线 | E34: M | F34: 0 | G34: 50 | H34: =F34*G34 -> 0 | I34: 定制烤漆踢脚线 | J34: 30
A35: 5 | C35: 圆弧踢脚线 | E35: 处 | F35: 0 | G35: 350 | H35: =F35*G35 -> 0 | J35: 200
A36: 6 | C36: 平铺 | E36: M2 | F36: 0 | G36: 40 | H36: =F36*G36 -> 0 | I36: 平铺，防潮垫，保护膜包含在内 | J36: 30
A37: 7 | C37: 人字/鱼骨/异形拼 | E37: M2 | F37: 0 | G37: 60 | H37: =F37*G37 -> 0 | I37: 平铺，防潮垫，保护膜包含在内 | J37: 55
A38: 8 | C38: 龙骨铺贴 | E38: M2 | F38: 0 | G38: 80 | H38: =F38*G38 -> 0 | I38: 木龙骨基层找平，间距30CM，门框位置加密 | J38: 65
A39: 9 | C39: 满胶铺贴 | E39: M2 | F39: 0 | G39: 150 | H39: =F39*G39 -> 0 | I39: 法国波士胶粘合剂（满胶铺贴） | J39: 120
A40: 10 | C40: 点胶铺贴 | E40: M2 | F40: 0 | G40: 100 | H40: =F40*G40 -> 0 | I40: 法国波士胶粘合剂（点胶铺贴） | J40: 80
...
