Workbook

Sheet 封面
A2: 全 包 设 计
A4: 项目：金地天元鸣望-8-2-602
A6: 日期： 年 月 日

Sheet 预算说明书 
A1: 山屿装饰设计有限公司告知书
A2: 欢迎您成为山屿设计的VIP客户，我们将会为您提供最超值和最优质的服务。为了使我们的合作能顺利进行，特此以书信的形式向您说明在施工过程中的相关内容及注意事项。
A3: 1 | B3: 预算书依照现有施工图纸所示内容、范围及结合市场材料、人工价格进行编制；预算材料按国家标准GB/T18580-2001执行。
A4: 2 | B4: 现场施工，如遇原建筑墙面空鼓、外立面或原始窗户渗漏水等原始缺陷的，由物业或业主（质保过期）负责维修。如需公司负责维修的，费用另计，且合同工期顺延；如业主装修项目时有前期土建或中央空调、地暖、新风等涉及第三方施工的，合同工期顺延。
A5: 3 | B5: 结构性梁、柱、承重墙不可敲除，如甲方需要敲除，则根据现场结构按实计算（需业主确定且有经物业同意的书面拆除方案并由第三方建筑单位出具可拆证明）。若业主需要扩建，扩建部分由业主自行办理审批手续或取得相关部门认可，且符合相关法律法规。若产生违建，由业主负责承担违建责任与违建的处理结果，与公司无关。
A6: 4 | B6: 其他确认可拆砖砌墙体在拆除过程中，如遇表面不可预测的钢筋混泥土结构的，费用另计；前期方案报价中没有明确拆除的，如开工后新增的墙地面保温层拆除、墙面粉刷层拆除、翻边拆除等，费用另计。
A7: 5 | B7: 申请装修许可证及物业管理处应缴纳的保险费、装修押金、垃圾外运等均由客户支付。公司报价内垃圾清运是指从室内工地清运到物业指定小区内堆放地点，若需公司负责装车外运的费用另计。多层（不含电梯房）装修垃圾清理费：多层（不含电梯房）三楼按10/㎡，四楼按15/㎡，五楼按20/㎡，六楼按25/㎡（按图纸面积计算）。全包的主材垃圾默认由公司统一清理，业主自行清理的提前告知公司。半包客户主材安装时产生的垃圾由商家负责清理，如需公司清理费用另计。
A8: 6 | B8: 小区运输材料上楼费：多层（不含电梯房）三楼按10/㎡，四楼按15/㎡，五楼按20/㎡，六楼按25/㎡（按图纸面积计算），如小区物业规定材料、垃圾需吊装运输的，费用由业主承担。
A9: 7 | B9: 所有工程款项（包括预算外签定联系单的新增项目）一律打到公司指定账户，严禁与私自交易，私自交易所产生的后果由客户自行负责，不列入公司保修范围之内。根据合同约定，节点验收三日内需完成支付款项，在此期间公司安排材料发货和施工安排，未在三日内支付，则工地处于停工状态。增加款应在增项施工前打款，如不缴纳乙方有权停止施工。凡涉及施工变更项目增减项的具体金额，统一由项目经理沟通确认，其他人员不得与业主私自约定。
A10: 8 | B10: 客户（甲方）自购材料，对其质量所引起的一切后果公司概不负责，同时不在公司保修，维修范围之内。
A11: 9 | B11: 如墙地砖铺贴为斜铺，人工费另增加20元/㎡。如为拼色、错位铺贴，人工费另增加20元/㎡。薄贴人工费另加20元/㎡，组合腰线（地砖走边）不在报价范围，另行增加按20元/m计算。750*1500湿贴上墙，人工费另增加20元/㎡,900*1800地砖铺贴人工补差40元/㎡，900*1800湿贴上墙，人工费另增加60元/㎡，地板长条砖人工费另增加50元/㎡，特殊规格小砖（70*200/70*300/100*100/100*200）人工费单独补差100元一平
A12: 10 | B12: 如需安装强排龙头，花洒，马桶等预埋件，需水电前确定好且需额外增加费用计算300元/个（报价详细说明）。油漆工艺墙面是滚刷工艺，顶面喷涂工艺，顶面需滚涂工艺另加10元/一平外框面积计算。空开如更换由业主自购。
A13: 11 | B13: 阳台墙砖铺贴，梁下口，门洞下口不贴砖，若客户指定要贴，后期脱落责任自负。天然大理石本身比较脆弱如有裂缝属正常现象，若需更换费用另计。半包中除过门石、窗台石外，其余石材由商家进行安装。石膏板吊顶为单层纸面石膏板，不增加欧松板基层（若需要挂吊灯等加固部分除外）侧面边吊欧松板加固。
A14: 12 | B14: 公司标配电线规格：1.5㎡、2.5㎡、4㎡。除空调外机线外特殊需求用6㎡电线按照使用量另收10元/m，如需电箱移位10㎡线由业主自己自行采购。水电标准施工项目中不含音响布线、监控布线、防盗系统布线、电动窗帘布线、电地暖布线、家庭智能系统布线、即热式电热水器布线、软水系统等， 只含一种热水器布线（燃气热水器布线、电热水器布线、太阳能热水器布线或空气能热水器布线。阳台不含热水布管。如需小循坏增加20元/平，大循环35元/平，如水电工程验收完工后需要调整改动，每调整一个点位另增加120元。
... A18: 16 | B18: 本报价未包含税金。双方所有约定均需以一式二份文字协议为准，公司任何员工给客户（甲方）的承诺以盖公章的书面说明为准，任何口头承诺均无效。
B19: 客户签字：＿＿＿＿＿＿＿ 日期： ＿＿＿＿＿＿＿＿

Sheet 辅材明细表
A1: 标准工程材料明细
A2: 类目 | B2: 材料项目 | C2: 材料品牌 | E2: 材料说明
A3: 水电 | B3: 冷热水管 | C3: 保利双色抗冲击系列 | E3: PPR管，均使用热水管铺设(主管¢25，壁厚4.2mm；支管¢25，壁厚4.2mm)，热水管做EVA保温处理。
B4: PVC管 | C4: 保利阻燃系列 | E4: 下水管改造，穿线管。强电红色，弱电蓝色。规格：D16、D20，壁厚1mm。
B5: 国标电线 | C5: 正泰阻燃线 | E5: 低烟、无卤阻燃线单芯铜线（聚氯乙烯绝缘）。灯头、双色线：1.5㎡；插座、壁挂空调：2.5㎡；主空调线：4㎡ ；厨房主线：4㎡；卫生间主线：4㎡；即热电热水器：4㎡
B6: 网线 | C6: 正泰 | E6: 超六类屏蔽网络线
B7: 电话线 | E7: 四芯电话线
B8: 电视线 | E8: 高清数字电视线
B9: 电线保护盖板 | C9: 保利 | E9: 可以有效防止意外触电事故的发生，避免施工过程中灰尘污染线头。
B10: 电工底盒 | E10: 插座开关底盒。
A11: 防水 | B11: 防水涂料 | C11: 保利防水（巧匠TX100，巨匠RX100柔性） | E11: 质保30年，标高2米，地面超强柔性，抗开裂；墙面易涂型粘接力强，贴砖牢。
A12: 瓦工 | B12: 胶泥 | C12: 意大利马贝C2TE | E12: 执行标准jc/t547-2017c2te，根据瓷砖大小变跟
A13: 木 工 材 料 | B13: 欧松板 | C13: 千年舟（环保等级ENF） | E13: 厚度：1.8cm；1.5cm；1.2cm；0.9cm
B14: 净醛石膏板 | C14: 德国可耐福（蓝晶系列） | E14: 0.95cm，用于室内吊顶、隔墙和贴面墙。
B15: 龙骨 | C15: 千年舟 | D15: 轻钢龙骨 | E15: 用于吊顶、隔墙基层工程等。
A16: 油漆 材料 | B16: 乳胶漆 | C16: 佐敦(悦和系列) | E16: 底层用于墙顶部饰面底涂，面层用于墙顶部饰面面涂。
B17: 乳胶漆腻子 | C17: 圣戈班 | E17: 厨卫耐水腻子 其他区域内墙腻子
B18: 界面剂 | C18: 意大利马贝界面剂G | E18: 墙面涂刷 增加墙面黏着力
B19: 防锈漆 | C19: 意大利马贝1k | E19: 进口防锈漆 处理钉眼防锈处理
B20: 专用复合保护膜 | C20: 公司定制 | D20: EPE＋石膏板 | E20: 成品保护。

Sheet 主材明细表
A1: 主材目录表
A2: 序号 | B2: 区 域 | C2: 品 牌
A3: 1 | B3: 封 阳 台 | C3: 沃伦/科 度/澳普利发
A4: 2 | B4: 中 央 空 调 | C4: 日立/东芝 /美的
A5: 3 | B5: 橱 柜 | C5: 铂屿定制（烤漆/嘉彩/丽特曼/爱格/可丽芙）
A6: 4 | B6: 衣 柜 | 装 饰 柜 | C6: 铂屿定制（烤漆/嘉彩/丽特曼/爱格/可丽芙）
A7: 5 | B7: 瓷 砖 | C7: 冠珠 | 欧 文 莱 | KT木纹砖| HBI
A8: 6 | B8: 木 地 板 | C8: 唯美金樽/乔艺/
A9: 7 | B9: 木 门 | 门 套 | C9: 烤 漆 门 | 衣柜柜门同色
A10: 8 | B10: 移 门 | C10: 铂屿定制 （杜格铝材，欧派克五金）
A11: 9 | B11: 卫 浴 | C11: 法 恩 莎 | 德国顾朗 | 汉斯格雅| 杜拉维特
A12: 10 | B12: 淋 浴 房 | C12: 朗格
A13: 11 | B13: 灯 具 | C13: 时 一
A14: 12 | B14: 开 关 面 板 | C14: 施耐德（珍铂）
... A18: 16 | B18: 石 材 | 岩 板 | C18: 德利丰| HBI

Sheet 半包报价模板
A1: 基础报价明细表
A2: 客户名称： | E2: 建筑面积（㎡）： | G2: 130 | H2: 工程地址：
A3: 编号 | C3: 工程项目 | E3: 单位 | F3: 数量 | G3: 工 程 造 价 | I3: 备 注
G4: 单价 | H4: 金额
A5: 【一、砌墙工程】 | D5: 面积（㎡)： | F5: 周长（m): | H5: 层高（m): | I5: 2.91 | J5: 成本
A6: 1 | C6: 内墙顶涂料铲除及打毛处理 | E6: M2 | F6: 0 | G6: 8 | H6: =F6*G6 -> 0 | I6: 1、人工费； 2、垃圾装袋运至小区指定点，如需要运到小区外费用另计。 | J6: 4
A7: 2 | C7: 120墙体拆除 | E7: M2 | F7: 0 | G7: 62 | H7: =F7*G7 -> 0 | I7: 1、指不违反物业规定的非承重墙； 2、人工费； 3、垃圾装袋运至小区指定点，如需要运到小区外费用另计。 | J7: 40
A8: 3 | C8: 240墙体拆除 | E8: M2 | F8: 0 | G8: 72 | H8: =F8*G8 -> 0 | I8: 1、指不违反物业规定的非承重墙； 2、人工费； 3、垃圾装袋运至小区指定点，如需要运到小区外费用另计。 | J8: 50
A9: 4 | C9: 构造墙切割 | E9: 处 | F9: 0 | G9: 1000 | H9: =F9*G9 -> 0 | I9: 1、指不违反物业规定的非承重墙； 2、人工费； 3、垃圾装袋运至小区指定点，如需要运到小区外费用另计。 | J9: 800
A10: 5 | C10: 横梁剥皮 | E10: 项 | F10: 0 | G10: 500 | H10: =F10*G10 -> 0 | I10: 1、指不违反物业规定的非承重墙； 2、人工费； 3、垃圾装袋运至小区指定点，如需要运到小区外费用另计。 | J10: 300
A11: 6 | C11: 原有飘窗拆除 | E11: M | F11: 0 | G11: 260 | H11: =F11*G11 -> 0 | I11: 1、人工费； 2、垃圾装袋运至小区指定点，如需要运到小区外费用另计。 3、如遇混凝土及钢结构飘窗费用另计 | J11: 200
A12: 7 | C12: 敲半墙 | E12: M2 | F12: 0 | G12: 118 | H12: =F12*G12 -> 0 | I12: 1、指不违反物业规定的非承重墙； 2、人工费； 3、垃圾装袋运至小区指定点，如需要运到小区外费用另计。 4、如遇轻质砖墙或空斗砖墙，需整体拆墙后，再重新砌墙粉刷，费用另计 | J12: 50
A13: 8 | C13: 挖半墙后墙面修补抹灰 | E13: M2 | F13: 0 | G13: 50 | H13: =F13*G13 -> 0 | I13: 水泥砂浆粉面抹灰 | J13: 30
A14: 9 | C14: 普通地梁浇筑 | E14: M | F14: =0.41+0.66+0.98+0.94+0.5+0.36 -> 3.85 | G14: 50 | H14: =F14*G14 -> 192.5 | I14: 1、强度32.5普通硅酸盐水泥； 2、瓜子片浇筑； 钢筋植入，打入植筋胶 3、现浇地梁高度≥200mm | J14: 35
A15: 10 | C15: 地梁浇筑 | E15: M | F15: 0 | G15: 220 | H15: =F15*G15 -> 0 | I15: 1、强度32.5普通硅酸盐水泥； 2、瓜子片浇筑； 钢筋植入，打入植筋胶 3、地板支模现浇地梁高度≥200mm | J15: 160
A16: 11 | C16: 快装龙骨隔墙（防水板/干湿区砌墙专用） | E16: M2 | F16: 0 | G16: 258 | H16: =F16*G16 -> 0 | I16: 1、使用快装龙骨+背衬板打底 （免焊龙骨规格34*34） 2、墙厚≤60mm，工程量按单面立面面积计。 | J16: 160
A17: 12 | C17: 快装龙骨隔墙（石膏板饰面） | E17: M2 | F17: 0 | G17: 208 | H17: =F17*G17 -> 0 | I17: 1、使用快装龙骨+石膏板 （免焊龙骨规格34*34） 2、墙厚≤80mm，工程量按单面立面面积计。 | J17: 125
A18: 13 | C18: 快装龙骨隔墙（欧松板打底/石膏板饰面） | E18: M2 | F18: 0 | G18: 328 | H18: =F18*G18 -> 0 | I18: 1、使用快装龙骨+石膏板+欧松板打底 （免焊龙骨规格34*34） 2、墙厚≤100mm，工程量按单面立面面积计。 | J18: 185
A19: 14 | C19: 多孔120红砖砌墙 | E19: M2 | F19: =(0.41+0.66+0.92+0.9+0.36+3.1+1.28+1.51+1.58+1.06+0.38+0.33+0.35+1.88+0.56+0.84+0.38+1.44+0.56+1.58)*I5 -> 58.4328 | G19: 188 | H19: =F19*G19 -> 10985.366 | I19: 1、使用多孔砖，强度32.5普通硅酸盐水泥砂浆砌筑； 2、墙厚≤120mm，工程量按单面立面面积计。4：墙面水泥砂浆抹灰 | J19: 128
A20: 15 | C20: 多孔240红砖砌墙 | E20: M2 | F20: =(0.22)*I5 -> 0.6402 | G20: 288 | H20: =F20*G20 -> 184.3776 | I20: 1、使用多孔砖，强度32.5普通硅酸盐水泥砂浆砌筑； 2、墙厚≤60mm，工程量按单面立面面积计。4：墙面水泥砂浆抹灰 | J20: 220
A21: 16 | C21: 砌墙弧形墙造型 | E21: 个 | F21: 1 | G21: 400 | H21: =F21*G21 -> 400 | I21: 1、弧形墙人工费； | J21: 300
A22: 17 | C22: 双面石膏板隔墙 | E22: M2 | F22: =(0.33+0.21+0.26+0.66)*2.41 -> 3.5186 | G22: 138 | H22: =F22*G22 -> 485.5668 | I22: 1、轻钢龙骨基架，间距≤400mm，双面封9.5mm厚纸面石膏板，全封闭不带门窗，墙厚950mm; 2、石膏板自攻螺丝钉固定，钉帽涂防锈漆，板接缝处填嵌缝石膏，粘帖专用绷带； | J22: 90
A23: 18 | C23: 石膏板隔墙隔音棉 | E23: M2 | F23: =SUM(F22) -> 3.5186 | G23: 30 | H23: =F23*G23 -> 105.558 | I23: 1、轻钢龙骨基架，间距≤400mm，双面封9mm厚纸面石膏板，全封闭不带门窗，墙厚120mm; 2、石膏板自攻螺丝钉固定，钉帽涂防锈漆，板接缝处填嵌缝石膏，粘帖专用绷带； 3、批腻子和面层装饰另计； 4、隔断内填充保温隔音材料费用另计； 5、工程量按单面立面面积计算； 6、弧形工艺上浮30%。 7、15MM欧松板找平，打底。 | J23: 20
A24: 20 | C24: 砖墙门洞过梁 | E24: 个 | F24: 5 | G24: 100 | H24: =F24*G24 -> 500 | I24: 混凝土过梁或4号角铁过梁1.0米以内为一个 | J24: 60
A25: 小计： | H25: =SUM(H6:H24) -> 12853.369
A26: 【二、客餐厅工程】 | D26: 面积（㎡)： | E26: 50 | F26: 周长（m): | G26: 40 | H26: 层高（m): | I26: 2.8
C27: 门槛石安装 | E27: M | G27: 120 | H27: =F27*G27 -> 0 | I27: 水泥黄沙铺贴（不足1米按1米算） | J27: 100
C28: 石材窗台板铺设 | E28: M | G28: 100 | H28: =F28*G28 -> 0 | I28: 1、轻工辅料，宽度≤300mm; 2、干性水泥砂浆铺贴，玻璃胶填缝； 3、不含抛光打蜡。 | J28: 80
C29: 成品保护 | E29: M2 | F29: =SUM(E26) -> 50 | G29: 12 | H29: =F29*G29 -> 600 | I29: 乙方提供成品保护材料对于施工完成的半成品及成品进行保护。 | J29: 12
A30: 防水 | C30: 地面水性防水涂料（地暖地面要算2遍） | E30: M2 | G30: 65 | H30: =F30*G30 -> 0 | I30: 1、地面清理，四周防水带，内外角防水贴，淋浴水管根套 2、一般墙面上返300mm 3、做24小时蓄水试验（甲方验收签字）； 4、不包含原地面装饰层拆除； 5、按实际涂刷面积计算工程量。 | J30: 35
C31: 墙面水性防水涂料 | E31: M2 | G31: 65 | H31: =F31*G31 -> 0 | I31: 1、墙面清理，四周防水带，内外角防水贴，淋浴水管根套 2、卫生间墙面涂刷2000mm； 3、做24小时蓄水试验（甲方验收签字）； 4、不包含原地面装饰层拆除； 5、按实际涂刷面积计算工程量。 | J31: 35
A32: 泥工贴砖 | C32: 800*800mm地砖（水泥砂浆粘贴） | E32: M2 | F32: 0 | G32: 150 | H32: =F32*G32 -> 0 | I32: 水泥黄沙铺贴，斜铺、错缝、不规则、走边铺贴费用另计，不含美缝、胶泥。 | J32: 90
C33: 600*1200mm地砖（水泥砂浆粘贴） | E33: M2 | F33: =E26 -> 50 | G33: 160 | H33: =F33*G33 -> 8000 | I33: 水泥黄沙铺贴，斜铺、错缝、不规则、走边铺贴费用另计，不含美缝、胶泥。 | J33: 100
C34: 750*1500mm地砖（水泥砂浆粘贴） | E34: M2 | F34: 0 | G34: 170 | H34: =F34*G34 -> 0 | I34: 水泥黄沙铺贴，斜铺、错缝、不规则、走边铺贴费用另计，不含美缝、胶泥。 | J34: 105
C35: 900*1800mm地砖（水泥砂浆粘贴） | E35: M2 | F35: 0 | G35: 200 | H35: =F35*G35 -> 0 | I35: 水泥黄沙铺贴，斜铺、错缝、不规则、走边铺贴费用另计，不含美缝、胶泥。 | J35: 120
C36: 200*700mm小砖（胶泥粘帖） | E36: M2 | F36: 0 | G36: 200 | H36: =F36*G36 -> 0 | I36: 1、轻工辅料， 2、马贝胶泥铺贴； | J36: 140
C37: 800*800mm墙砖（胶泥粘帖） | E37: M2 | F37: 0 | G37: 160 | H37: =F37*G37 -> 0 | I37: 1、轻工辅料， 2、马贝胶泥铺贴； | J37: 100
C38: 600*1200mm墙砖（胶泥粘帖） | E38: M2 | F38: 0 | G38: 170 | H38: =F38*G38 -> 0 | I38: 1、轻工辅料， 2、马贝胶泥铺贴； | J38: 105
C39: 750*1500mm墙砖（胶泥粘帖） | E39: M2 | F39: 0 | G39: 180 | H39: =F39*G39 -> 0 | I39: 1、轻工辅料， 2、马贝胶泥铺贴； | J39: 110
C40: 900*1800mm墙砖（胶泥粘帖） | E40: M2 | F40: 0 | G40: 220 | H40: =F40*G40 -> 0 | I40: 1、轻工辅料， 2、马贝胶泥铺贴； | J40: 130
...

Sheet 主材报价模板 
A1: 主材报价明细表
A2: 客户名称： | E2: 建筑面积（㎡）： | G2: =半包报价模板!G2 -> 130 | H2: 工程地址： | I2: =半包报价模板!I2 -> 0
A3: 编号 | C3: 材料名称 | D3: 规格 | E3: 单位 | F3: 数量 | G3: 工 程 造 价 | I3: 品牌
G4: 单价 | H4: 金额
A5: 【一、瓷 砖】
A6: 德祥筑家 | C6: 广东一线冠珠 | D6: 600*1200 | E6: M2 | F6: 0 | G6: 105 | H6: =F6*G6 -> 0 | I6: 冠珠柔/亮光砖 | J6: 65
C7: 广东一线冠珠 | D7: 750*1500 | E7: M2 | F7: =半包报价模板!F34*1.15 -> 0 | G7: 113 | H7: =F7*G7 -> 0 | I7: 冠珠柔/亮光砖 | J7: 70
C8: 广东一线冠珠 | D8: 600*1200 | E8: M2 | F8: =半包报价模板!F35*1.15 -> 0 | G8: 153 | H8: =F8*G8 -> 0 | I8: 冠珠莱姆石质感砖 | J8: 95
C9: 广东一线冠珠 | D9: 750*1500 | E9: M2 | F9: =半包报价模板!F36*1.15 -> 0 | G9: 170 | H9: =F9*G9 -> 0 | I9: 冠珠莱姆石质感砖 | J9: 105
C10: 道远莱姆石质感砖 | D10: 600*1200 | E10: M2 | G10: 138 | H10: =F10*G10 -> 0 | I10: 道远 | J10: 85.5
C11: KT木纹板 | D11: 600*1200 | E11: M2 | G11: 105 | H11: =F11*G11 -> 0 | I11: KT木纹板 | J11: 65
C12: KT木纹板（阿童木微模质感面） | D12: 600*1200 | E12: M2 | G12: 138 | H12: =F12*G12 -> 0 | I12: KT木纹板（阿童木微模质感面） | J12: 87.5
C13: kt南美橡木（微模质感面） | D13: 200*1200 | E13: M2 | F13: =半包报价模板!F258*1.15 -> 0 | G13: 113 | H13: =F13*G13 -> 0 | I13: kt南美橡木（微模质感面） | J13: 70
C14: 广东一线欧文莱 | D14: 600*1200 | E14: M2 | F14: 0 | G14: 190 | H14: =F14*G14 -> 0 | I14: 广东一线欧文莱 | J14: 118
C15: 广东一线欧文莱 | D15: 750*1500 | E15: M2 | F15: 0 | G15: 208 | H15: =F15*G15 -> 0 | I15: 广东一线欧文莱 | J15: 128
C16: 广东一线欧文莱 | D16: 900*1800 | E16: M2 | F16: 0 | G16: 367 | H16: =F16*G16 -> 0 | I16: 广东一线欧文莱 | J16: 228
C17: 古堡砖 | D17: 多规格 | E17: M2 | F17: 0 | G17: 230 | H17: =F17*G17 -> 0 | I17: 土豆/印象 | J17: 145
C18: 定制小砖 | D18: 700*200/750*300/120*120 | E18: M2 | F18: 0 | G18: 280 | H18: =F18*G18 -> 0 | I18: 定制小砖 | J18: 190
A21: HBI | C21: 广东一线HBI | D21: 600*1200 | E21: M2 | F21: 0 | G21: 113 | H21: =F21*G21 -> 0 | I21: 广东一线HBI瓷砖（柔/亮面） | J21: 70
C22: 广东一线HBI | D22: 750*1500 | E22: M2 | F22: 0 | G22: 120 | H22: =F22*G22 -> 0 | I22: 广东一线HBI瓷砖（柔/亮面） | J22: 75
C23: 广东一线HBI | D23: 750*1500 | E23: M2 | F23: 0 | G23: 162 | H23: =F23*G23 -> 0 | I23: 广东一线HBI瓷砖（凹凸面） | J23: 100
C24: 广东一线HBI | D24: 900*1800 | E24: M2 | F24: 0 | G24: 218 | H24: =F24*G24 -> 0 | I24: 广东一线HBI瓷砖 | J24: 135
H25: =SUM(H6:H24) -> 0
A26: 【二、美 缝】
A27: 1 | C27: 美缝 | E27: M2 | F27: 0 | G27: 25 | H27: =F27*G27 -> 0 | I27: 梵聚匠/汉高百得 | J27: 16
A28: 2 | C28: 打胶收口 | E28: M2 | F28: 125 | G28: 10 | H28: =F28*G28 -> 1250 | I28: 瓦克（外框面积计算） | J28: 7
A29: 3 | C29: 小砖环氧彩砂 | E29: M2 | F29: 1 | G29: 180 | H29: =F29*G29 -> 180 | I29: 梵聚匠/汉高百得（规格10*100/100/200）压缝工艺（调色增加500元一个色） | J29: 100
A30: 4 | C30: 马贝环氧彩砂 | E30: 米 | F30: 1 | G30: 20 | H30: =F30*G30 -> 20 | I30: 马贝环氧彩砂（平缝工艺） | J30: 12
A31: 小计： | H31: =SUM(H27:H30) -> 1450
A32: 【三、木 地 板】
A33: 1 | C33: 木地板 | E33: M2 | F33: 0 | G33: 218 | H33: =F33*G33 -> 0 | I33: 根据款式每款价格都不一样
A34: 2 | C34: 木龙骨 | E34: M2 | F34: 0 | G34: 80 | H34: =F34*G34 -> 0 | I34: 木龙骨基层找平，间距30CM，门框位置加密 | J34: 50
A35: 3 | C35: 饰面木质踢脚线 | E35: M | F35: 0 | G35: 38 | H35: =F35*G35 -> 0 | I35: 成品木质踢脚线（无盯眼安装） | J35: 25
A36: 4 | C36: 烤漆踢脚线 | E36: M | G36: 50 | H36: =F36*G36 -> 0 | I36: 定制烤漆踢脚线 | J36: 30
A37: 5 | C37: 圆弧踢脚线 | E37: 处 | G37: 350 | J37: 200
A38: 6 | C38: 平铺 | E38: M2 | G38: 40 | H38: =F38*G38 -> 0 | I38: 平铺，防潮垫，保护膜包含在内 | J38: 30
A39: 7 | C39: 满胶铺贴 | E39: M2 | G39: 150 | H39: =F39*G39 -> 0 | I39: 法国波士胶粘合剂（满胶铺贴） | J39: 120
A40: 8 | C40: 点胶铺贴 | E40: M2 | G40: 100 | H40: =F40*G40 -> 0 | I40: 法国波士胶粘合剂（点胶铺贴） | J40: 80
A41: 9 | C41: 铝合金踢脚线 | E41: M | G41: 40 | H41: =F41*G41 -> 0 | I41: 成品铝合金踢脚线（根据款式选定） | J41: 20
A42: 10 | C42: 不锈钢踢脚线 | E42: M | G42: 58 | H42: =F42*G42 -> 0 | I42: 不锈钢踢脚线安装（根据款式选定） | J42: 35
...

Sheet 全屋窗帘+百叶
A1: 全屋窗帘+百叶报价表
A2: 客户名称： | C2: =半包报价模板!C2 -> 0 | D2: 联系电话： | G2: 建筑面积： | H2: =半包报价模板!G2 -> 130 | I2: 工程地点： | M2: =半包报价模板!I2 -> 0
A3: 序号 | B3: 编号 | C3: 工程项目 | D3: 品 牌 | E3: 单 位 | F3: 数 量 | G3: 单 价 | H3: 金额 | K3: 备 注
A4: 【一、客餐厅】
B5: 1 | C5: 白色铝合金轨道 | D5: 山 屿 设 计 | E5: M | F5: 0 | G5: 20 | H5: =F5*G5 -> 0 | K5: 轨道、安装
B6: 2 | C6: 帝缦羊绒现代麻 | D6: 山 屿 设 计 | E6: M | F6: =F5*2 -> 0 | G6: =68*1.4 -> 95.2 | H6: =F6*G6 -> 0 | K6: 含布料、制作加工、高温定型。
B7: 3 | C7: 本色纱 | D7: 山 屿 设 计 | E7: M | F7: =F6 -> 0 | G7: =35*1.4 -> 49 | H7: =F7*G7 -> 0 | K7: 含纱、制作加工
A8: 【二、主卧】
B9: 1 | C9: 白色铝合金轨道 | D9: 山 屿 设 计 | E9: M | F9: 0 | G9: 20 | H9: =F9*G9 -> 0 | K9: 轨道、安装
B10: 2 | C10: 帝缦羊绒现代麻 | D10: 山 屿 设 计 | E10: M | F10: =F9*2 -> 0 | G10: =68*1.4 -> 95.2 | H10: =F10*G10 -> 0 | K10: 含布料、制作加工、高温定型。
B11: 3 | C11: 本色纱 | D11: 山 屿 设 计 | E11: M | F11: =F10 -> 0 | G11: =35*1.4 -> 49 | H11: =F11*G11 -> 0 | K11: 含纱、制作加工
A12: 【三、南次卧】
B13: 1 | C13: 白色铝合金轨道 | D13: 山 屿 设 计 | E13: M | F13: 0 | G13: 20 | H13: =F13*G13 -> 0 | K13: 轨道、安装
B14: 2 | C14: 帝缦羊绒现代麻 | D14: 山 屿 设 计 | E14: M | F14: =F13*2 -> 0 | G14: =68*1.4 -> 95.2 | H14: =F14*G14 -> 0 | K14: 含布料、制作加工、高温定型。
B15: 3 | C15: 本色纱 | D15: 山 屿 设 计 | E15: M | F15: =F14 -> 0 | G15: =35*1.4 -> 49 | H15: =F15*G15 -> 0 | K15: 含纱、制作加工
A16: 【四、北次卧】
B17: 1 | C17: 白色铝合金轨道 | D17: 山 屿 设 计 | E17: M | F17: 0 | G17: 20 | H17: =F17*G17 -> 0 | K17: 轨道、安装
B18: 2 | C18: 帝缦羊绒现代麻 | D18: 山 屿 设 计 | E18: M | F18: =F17*2 -> 0 | G18: =68*1.4 -> 95.2 | H18: =F18*G18 -> 0 | K18: 含布料、制作加工、高温定型。
B19: 3 | C19: 本色纱 | D19: 山 屿 设 计 | E19: M | F19: =F18 -> 0 | G19: =35*1.4 -> 49 | H19: =F19*G19 -> 0 | K19: 含纱、制作加工
A20: 【四、北客房】
B21: 1 | C21: 白色铝合金轨道 | D21: 山 屿 设 计 | E21: M | F21: 0 | G21: 20 | H21: =F21*G21 -> 0 | K21: 轨道、安装
B22: 2 | C22: 帝缦羊绒现代麻 | D22: 山 屿 设 计 | E22: M | F22: =F21*2 -> 0 | G22: =68*1.4 -> 95.2 | H22: =F22*G22 -> 0 | K22: 含布料、制作加工、高温定型。
B23: 3 | C23: 本色纱 | D23: 山 屿 设 计 | E23: M | F23: =F22 -> 0 | G23: =35*1.4 -> 49 | H23: =F23*G23 -> 0 | K23: 含纱、制作加工
A24: 【五、主卫】
B25: 1 | C25: PVC厂字型百叶（防水） | D25: 山 屿 设 计 | E25: M2 | F25: 0 | G25: =105*1.4 -> 147 | H25: =F25*G25 -> 0 | K25: 1、实际设计选材后超出暂估金额部分需另补差价。
A26: 【六、公卫】
B27: 1 | C27: PVC厂字型百叶（防水） | D27: 山 屿 设 计 | E27: M2 | F27: 0 | G27: =105*1.4 -> 147 | H27: =F27*G27 -> 0 | K27: 1、实际设计选材后超出暂估金额部分需另补差价。
A28: 【七、餐厅】
B29: 1 | C29: PVC厂字型百叶（防水） | D29: 山 屿 设 计 | E29: M2 | F29: 0 | G29: =105*1.4 -> 147 | H29: =F29*G29 -> 0 | K29: 1、实际设计选材后超出暂估金额部分需另补差价。
A30: 【八、书房】
B31: 1 | C31: PVC厂字型百叶（防水） | D31: 山 屿 设 计 | E31: M2 | F31: 0 | G31: =105*1.4 -> 147 | H31: =F31*G31 -> 0 | K31: 1、实际设计选材后超出暂估金额部分需另补差价。
A32: 【九、厨房】
B33: 1 | C33: PVC厂字型百叶（防水） | D33: 山 屿 设 计 | E33: M2 | F33: 0 | G33: =105*1.4 -> 147 | H33: =F33*G33 -> 0 | K33: 1、实际设计选材后超出暂估金额部分需另补差价。
B34: （1） | C34: 小计 | D34: 元 | G34: =SUM(H5:J33) -> 0
B35: （2） | C35: 服务费 | D35: 元 | G35: =G34*0.1 -> 0 | K35: 服务费10%
B36: （3） | C36: 总计 | D36: 元 | G36: =SUM(G34:G35) -> 0

Sheet 封 窗 户|主卫玻璃隔断及门
A1: 系统门窗分项组价报价单
A2: 客户经理： | G2: 联系电话:
A3: 技术落地负责人： | G3: 联系电话：
A4: 项目名称：秀宸华府 | G4: 报价单编号：LS202411221100
A5: 业主信息： | G5: 联系电话:
A6: 页码：1页 | G6: 报价日期：2024年11月22日
A7: 报价复核负责人： | G7: 报价有效期：30天
A8: 所采用方案产品内容价格清单
A9: 序号 | B9: 安装位置 | C9: 门窗系列 | D9: 系列型号 | E9: 门窗编号 | F9: 表面处理颜色 | G9: 门窗宽度 | H9: 门窗高度 | I9: 开扇数量 | J9: 玻璃规格 | K9: 工程量（㎡） | L9: 框体单价 | M9: 开扇单价 | N9: 工程总牌价 | O9: 备注
A10: 1 | B10: 南阳台 | C10: 伯屿 | D10: 118系列窗纱一体外开系统窗3.0 | E10: C1 | F10: 外灰内灰 | G10: 8260 | H10: 2440 | I10: 3 | J10: 标配5+27A+5 | K10: =G10*H10/1000000 -> 20.1544 | L10: 780 | M10: 700 | N10: =M10*I10+K10*L10 -> 17820.432
A11: 2 | B11: 北阳台 | C11: 伯屿 | D11: 118系列窗纱一体外开系统窗3.0 | E11: C1 | F11: 外灰内灰 | G11: 2430 | H11: 2380 | I11: 1 | J11: 标配5+27A+5 | K11: =G11*H11/1000000 -> 5.7834 | L11: 780 | M11: 700 | N11: =M11*I11+K11*L11 -> 5211.052
A12: 3 | B12: 书房 | C12: 伯屿 | D12: 118系列窗纱一体外开系统窗3.0 | E12: C1 | F12: 外灰内灰 | G12: 0 | H12: 0 | I12: 0 | J12: 标配5+27A+5 | K12: =G12*H12/1000000 -> 0 | L12: 780 | M12: 700 | N12: =M12*I12+K12*L12 -> 0
B13: 产品标配内容合计 | K13: =SUM(K10:K12) -> 25.9378 | N13: =SUM(N10:N12) -> 23031.484
A14: 辅材与增配溢价部分价格清单
A15: 序号 | B15: 安装位置 | C15: 品牌说明 | D15: 增配内容 | E15: 规格说明 | J15: 单 位 | K15: 工程量 | L15: 单价 | M15: 工程直供价 | N15: 备注
A16: 1 | B16: 北阳台 | C16: 旗滨/南玻 | D16: 玻璃增厚 | E16: 升级8+15A+8中空：1.73*2.38=1块 | J16: ㎡ | K16: =1.73*2.38 -> 4.1174 | L16: 180 | M16: =L16*K16 -> 741.132
A17: 1 | B17: 南阳台 | C17: 旗滨/南玻 | D17: 玻璃增厚 | E17: 升级8+15A+8中空：2.28*2.44=2块 | J17: ㎡ | K17: =2.28*2.44*2 -> 11.1264 | L17: 180 | M17: =L17*K17 -> 2002.752
A18: 2 | B18: 南阳台 | C18: 旗滨/南玻 | D18: 玻璃升级 | E18: 升级LOW-E玻璃 | J18: ㎡ | K18: =K13 -> 25.9378 | L18: 60 | M18: =L18*K18 -> 1556.268
A19: 3 | B19: 南阳台 | C19: 伯屿 | D19: 立柱 | E19: 120方管立柱 | J19: 根 | K19: 0 | L19: 150 | M19: =L19*K19 -> 0
A20: 4 | B20: 主卫 | E20: 玻璃平开门 | J20: 套 | K20: 0 | L20: 1000 | M20: =L20*K20 -> 0
A21: 5 | B21: 玻璃隔断 | J21: ㎡ | K21: 0 | L21: 400 | M21: =L21*K21 -> 0
A22: 3 | B22: 主卫 | D22: 铝合金玻璃平开门 | E22: 8mm油砂玻璃 | J22: 套 | K22: 0 | L22: 1800 | M22: =L22*K22 -> 0
A23: 4 | B23: 公卫 | D23: 铝合金玻璃平开门 | E23: 8mm油砂玻璃 | J23: 套 | K23: 0 | L23: 1800 | M23: =L23*K23 -> 0
A24: 5 | B24: 书房 | D24: 三联动极窄移门 | E24: 8mm单白玻璃 | J24: m² | K24: 0 | L24: 650 | M24: =L24*K24 -> 0 | N24: 连动带阻尼
A25: 6 | B25: 次卧 | D25: 室内极窄两移移门 | E25: 8mm单白玻璃 | J25: m² | K25: 0 | L25: 480 | M25: =L25*K25 -> 0
A26: 7 | B26: 厨房 | D26: 三联动极窄移门 | E26: 8mm单白玻璃 | J26: m² | K26: 0 | L26: 650 | M26: =L26*K26 -> 0 | N26: L型折角
A27: 8 | B27: 厨房 | D27: 室内极窄两移移门 | E27: 8mm单白玻璃 | J27: m² | K27: 0 | L27: 480 | M27: =L27*K27 -> 0
A28: 6 | B28: 封窗 | D28: 吊装与安装 | E28: 特殊规格的窗框以及玻璃的吊运上楼以及多人抬运安装（含风险费） | J28: 套 | K28: 1 | L28: 800 | M28: =L28*K28 -> 800
B29: 产品增配内容合计 | M29: =SUM(M17:M28) -> 4359.02
B30: 产品+施工合同总价款 | M30: =M29+N13 -> 27390.504
A31: 注：对以上工程报价的产品参数和细节要素作如下陈述：
A32: 1.产品系列采用：外开窗纱一体平开窗
A33: 2.型材配置为：6063-T5铝材，118系列壁厚3.0mm.
A34: 3.节能配置为：国标PA66+25%玻璃纤维隔热条
A35: 4.密封配置为：海达EPDM建筑密封胶条
A36: 5.此总报价含门窗生产制作、阳光房原材料费、含玻璃费、含安装费，含运输费、含吊运费；不含税费。（如若开票，票面税金由用户方承担）
A37: 6.材料生产说明：所有材料配置型材6063-T5材质，五金乔洛夫

Sheet 家电
A2: 客户名称： | D2: 联系电话： | G2: 建筑面积： | H2: =[1]后续设计造型!H2 -> 118 | I2: =[1]后续设计造型!M2 -> 湖上云庭2-104
A3: 序号 | B3: 编号 | C3: 工程项目 | D3: 品 牌 | E3: 单 位 | F3: 数 量 | G3: 单 价 | H3: 金额 | K3: 备 注
B4: 1 | C4: 油烟机 | D4: 方太 | E4: 项 | F4: 1 | G4: =4800 -> 4800 | H4: =F4*G4 -> 4800 | K4: 方太 CXW-358-01-Y8
B5: 2 | C5: 燃气灶 | D5: 方太 | E5: 项 | F5: 1 | G5: =3160 -> 3160 | H5: =F5*G5 -> 3160 | K5: 方太 01-J3
B6: 3 | C6: 嵌入式洗碗机 | D6: 方太 | E6: 项 | F6: 1 | G6: =5400 -> 5400 | H6: =F6*G6 -> 5400 | K6: 方太 JBCD7E-04-H1
B7: 4 | C7: 蒸烤烹饪机 | D7: 方太 | E7: 项 | F7: 1 | G7: 5015 | H7: =F7*G7 -> 5015 | K7: 方太 ZK42-F2.i
B8: 4 | C8: 油烟机 | D8: 卡萨帝 | E8: 项 | F8: 0 | G8: =5999 -> 5999 | H8: =F8*G8 -> 0
B9: 5 | C9: 嵌入式洗碗机 | D9: 卡萨帝 | E9: 项 | F9: 0 | G9: =9999 -> 9999 | H9: =F9*G9 -> 0
B10: 5 | C10: 黑珍珠洗烘套装 | D10: colmo | E10: 项 | F10: 1 | G10: 11998 | H10: =F10*G10 -> 11998 | K10: CGU10H-C3+CHZ10H-C3
B11: 6 | C11: 冰箱 | D11: colmo | E11: 项 | F11: 1 | G11: 11200 | H11: =F11*G11 -> 11200 | K11: CRBUS703N-X1
B12: （1） | C12: 合计造价 | D12: 元 | G12: =SUM(H4:J11) -> 41573

Sheet 电器
A1: 电器报价表
A2: 客户名称： | C2: =半包报价模板!C2 -> 0 | D2: 联系电话： | G2: 工程地址： | I2: =半包报价模板!I2 -> 0
A3: 序号 | B3: 编号 | C3: 工程项目 | D3: 品 牌 | E3: 单 位 | F3: 数 量 | G3: 单 价 | H3: 金额 | K3: 备 注
B4: 1 | C4: 投影仪 | D4: 坚 果 | E4: 项 | F4: 1 | G4: 5000 | H4: =F4*G4 -> 5000
B5: 2 | C5: 电视机 | D5: 小 米 | E5: 项 | F5: 1 | G5: 5000 | H5: =F5*G5 -> 5000 | K5: 85寸电视机
B6: 3 | C6: 洗烘一体机 | D6: 西 门 子 | E6: 项 | F6: 1 | G6: 5000 | H6: =F6*G6 -> 5000 | K6: 10公斤
B7: 4 | C7: 咖啡机 | D7: 苏 泊 尔 | E7: 项 | F7: 1 | G7: 1000 | H7: =F7*G7 -> 1000
B8: 5 | C8: 空气净化器 | D8: / | E8: 项 | F8: 1 | G8: 5000 | H8: =F8*G8 -> 5000
B9: 6 | C9: 饮水机 | D9: / | E9: 项 | F9: 1 | G9: 2000 | H9: =F9*G9 -> 2000
B10: 7 | C10: 微波炉 | D10: 东 姿 | E10: 项 | F10: 1 | G10: 2000 | H10: =F10*G10 -> 2000
B11: 8 | C11: 电饭煲 | D11: / | E11: 项 | F11: 1 | G11: 1000 | H11: =F11*G11 -> 1000
B12: （1） | C12: 合计造价 | D12: 元 | G12: =SUM(H4:J11) -> 26000

Sheet 全案汇总 
A1: 汇 总 表
A2: 客户名称： | C2: =半包报价模板!C2 -> 0 | D2: 联系电话： | G2: 建筑面积： | H2: 125 | I2: 工程地址：
A3: 序号 | B3: 编号 | C3: 工程项目 | D3: 品 牌 | E3: 单 位 | F3: 数 量 | G3: 单 价 | H3: 金额 | K3: 折后价 | L3: 备 注
B4: 1 | C4: 中央空调 | D4: 日立 | E4: 项 | F4: 1 | G4: 42600 | H4: 0 | L4: 1、日立水墅适中央空调系统，2.一拖四
B5: 1 | C5: 风管机 | D5: 美 的 | E5: 项 | F5: 0 | G5: 16000 | H5: =F5*G5 -> 0 | L5: 1、详见明细单。三台风管机
B6: 2 | C6: 挂 机 | D6: 美 的 | E6: 项 | F6: 0 | G6: 4200 | H6: =F6*G6 -> 0 | L6: 1、详见明细单。两台挂机
B7: 3 | C7: 地 暖 | D7: 日立 | E7: 项 | F7: 1 | G7: 9700 | H7: 0 | L7: 1、水地暖系列
B8: 3 | C8: 新 风 | D8: 曼瑞德 | E8: 项 | F8: 1 | G8: 11500 | H8: 0 | L8: 1、详中央新风除湿系统（曼瑞德）
B9: 4 | C9: 封 窗 户 | D9: 丰 维 | E9: 项 | F9: 1 | G9: 36800 | H9: 0 | L9: 1、详见明细单。
B10: 4 | C10: 家 具 | D10: 山 屿 设 计 | E10: 项 | F10: 0 | G10: =#REF! -> #REF! | H10: =F10*G10 -> #REF! | L10: 1、详见明细单。2、暂估价格，实际设计选材后超出暂估金额部分需另补差价。
B11: 6 | C11: 家 电 | E11: 项 | F11: 0 | G11: =电器!G12 -> 26000 | H11: =F11*G11 -> 0 | L11: 1、详见明细单。2、暂估价格，实际设计选材后超出暂估金额部分需另补差价。
B12: 5 | C12: 灯 具 | D12: 时 一 | E12: 项 | F12: 0 | G12: 6000 | H12: =F12*G12 -> 0 | L12: 1、灯具暂估价格，实际设计选材后超出暂估金额部分需另补差价。
B13: 8 | C13: 窗 帘 | D13: 山 屿 设 计 | E13: 项 | F13: 0 | G13: 5000 | H13: =F13*G13 -> 0 | L13: 1、窗帘暂估价格，实际设计选材后超出暂估金额部分需另补差价。
B14: 6 | C14: 基础工程 | D14: 山 屿 设 计 | E14: 项 | F14: 1 | G14: =半包报价模板!G349 -> #VALUE! | H14: =F14*G14 -> #VALUE! | K14: 145000 | L14: 1、详见明细单。
B15: 7 | C15: 主材工程 | D15: 山 屿 设 计 | E15: 项 | F15: 1 | G15: ='主材报价模板 '!G132 -> 26826.855 | H15: =F15*G15 -> 26826.855 | K15: 76000 | L15: 1、详见明细单。
B16: 8 | C16: 铂屿木作定制 | D16: 铂 屿 定制 | E16: 项 | F16: 0 | L16: 1、详见明细单。
B17: 9 | C17: 整木衣柜定制 | D17: 铂 屿 定 制 | E17: 项 | F17: 0 | L17: 1、详见明细单。
B18: 10 | C18: 设计费 | D18: 山 屿 设 计 | E18: 项 | F18: 1 | G18: 120 | H18: =SUM(H2*G18) -> 15000 | K18: =SUM(H18) -> 15000 | L18: 1、按实际建筑面积计算120元/㎡
B19: 10 | C19: 施工图制图费 | D19: 山 屿 设 计 | E19: 项 | F19: 0 | G19: =H2*60 -> 7500 | H19: =F19*G19 -> 0 | L19: 1、按实际建筑面积计算60元/㎡
A20: 【工程汇总】 | K20: =SUM(K14:K17) -> 221000
A21: 【工程＋设计费汇总】 | K21: =SUM(K20+K18) -> 236000

Sheet 工程变动
A1: 工程变动明细表
A2: 客户名称： | E2: 建筑面积（㎡）： | G2: =半包报价模板!G2 -> 130 | H2: 工程地址： | I2: =半包报价模板!I2 -> 0
A3: 编号 | C3: 工程项目 | E3: 单位 | F3: 数量 | G3: 工 程 造 价 | I3: 备 注
G4: 单价 | H4: 金额
A5: 【一、工程新加变动】 | D5: 面积（㎡)： | F5: 周长（m): | H5: 层高（m):
A6: 1、阳台工程
A7: 1 | C7: 吊顶凹槽造型/线型灯 | E7: M | F7: 2.56 | G7: 50 | H7: =F7*G7 -> 128 | I7: 留槽工艺
A8: 2 | C8: 石膏板吊平顶 | E8: M2 | F8: 3.3 | G8: 168 | H8: =F8*G8 -> 554.4 | I8: 1、轻钢骨架，间距一般为400mm,打孔下膨胀螺栓固定； 2、9.5mm厚纸面石膏板罩面，自攻螺丝钉固定，钉眼点涂防锈漆，石膏板接缝处填嵌石膏，粘帖专用绷带；
A9: 2、客餐厅工程
A10: 1 | C10: 石膏板单级走边（≤200mm） | E10: M | F10: 3.5 | G10: 80 | H10: =F10*G10 -> 280 | I10: 木板基层，石膏板封边，宽度少于20mm
A11: 2 | C11: 石膏板异性造型 | E11: M2 | F11: =1.1*(0.8+0.74) -> 1.694 | G11: 553.1 | H11: =F11*G11 -> 936.9514 | I11: 1、欧松板基层； 2、9.5mm厚纸面石膏板罩面，自攻螺丝钉固定，钉眼点涂防锈漆，石膏板接缝处填嵌石膏，粘帖专用绷带；
A12: 2 | C12: 木作门洞过梁 | E12: 个 | F12: 1 | G12: 180 | H12: =F12*G12 -> 180 | I12: 1、欧松板基层； 2、9.5mm厚纸面石膏板罩面，自攻螺丝钉固定，钉眼点涂防锈漆，石膏板接缝处填嵌石膏，粘帖专用绷带；
A13: 3、次卧工程
A14: 1 | C14: 石膏板单级走边（≤200mm） | E14: M | F14: =0.64+0.64+2.69 -> 3.97 | G14: 80 | H14: =F14*G14 -> 317.6 | I14: 木板基层，石膏板封边，宽度少于20mm
A15: 4、多功能区工程
A16: 1 | C16: 空调出风或回风口框架 | E16: M | F16: 3.4 | G16: 100 | H16: =F16*G16 -> 340 | I16: 松木档框架，长度≤2000mm
A17: 小计： | H17: =SUM(H7:H16) -> 2736.9514
A18: 【二、工程减少变动】 | D18: 面积（㎡)： | F18: 周长（m): | H18: 层高（m):
A19: 1、阳台工程
A20: 1 | C20: 石膏板单级走边（≤200mm） | E20: M | F20: -3 | G20: 80 | H20: =F20*G20 -> -240 | I20: 木板基层，石膏板封边，宽度少于20mm
A21: 1、次卧工程
A22: 1 | C22: 石膏板吊平顶 | E22: M2 | F22: -0.83 | G22: 168 | H22: =F22*G22 -> -139.44 | I22: 1、轻钢骨架，间距一般为400mm,打孔下膨胀螺栓固定； 2、9.5mm厚纸面石膏板罩面，自攻螺丝钉固定，钉眼点涂防锈漆，石膏板接缝处填嵌石膏，粘帖专用绷带；
A23: 2 | C23: 石膏板普通单层边吊（≤300mm） | E23: M2 | F23: =-0.83*2 -> -1.66 | G23: 208 | H23: =F23*G23 -> -345.28 | I23: 1、轻钢骨架，间距一般为400mm,打孔下膨胀螺栓固定； 2、9.5mm厚纸面石膏板罩面，自攻螺丝钉固定，钉眼点涂防锈漆，石膏板接缝处填嵌石膏，粘帖专用绷带； 3、宽度不大于60mm。
A24: 小计： | H24: =SUM(H20:H23) -> -724.72
A25: 【十二、工程汇总】
B26: （1） | C26: 直接费 | E26: 元 | G26: =H17+H24 -> 2012.2314
B27: （2） | C27: 管理费 | E27: 元 | G27: 0 | I27: 管理费统一按工程总价10%计算。
B28: （3） | C28: 税金 | E28: 元 | I28: 税金统一按工程总价6%计算。 | K28: =G26*0.35 -> 704.28099

Sheet 土建
A2: 【一、拆除工程】
A3: 编号 | C3: 工程项目 | E3: 单位 | F3: 数量 | I3: 备 注
G4: 山屿单价 | H4: 金额
A5: 1 | C5: 120墙体拆除 | E5: M2 | G5: 78 | H5: =F5*G5 -> 0 | I5: 1、指不违反物业规定的非承重墙； 2、人工费； 3、垃圾装袋运至小区指定点，如需要运到小区外费用另计。
A6: 2 | C6: 240墙体拆除 | E6: M2 | G6: 88 | H6: =F6*G6 -> 0 | I6: 1、指不违反物业规定的非承重墙； 2、人工费； 3、垃圾装袋运至小区指定点，如需要运到小区外费用另计。
A7: 3 | C7: 敲半墙 | E7: M2 | G7: 118 | H7: =F7*G7 -> 0 | I7: 1、指不违反物业规定的非承重墙； 2、人工费； 3、垃圾装袋运至小区指定点，如需要运到小区外费用另计。 4、如遇轻质砖墙或空斗砖墙，需整体拆墙后，再重新砌墙粉刷，费用另计
A8: 4 | C8: 挖半墙后墙面修补抹灰 | E8: M2 | G8: 50 | H8: =F8*G8 -> 0 | I8: 水泥砂浆粉面抹灰
A9: 5 | C9: 地下室混凝土墙体切割 | E9: 项 | G9: 800 | H9: =F9*G9 -> 0 | I9: 1、拆除前客户签订免责协议。 2、人工机械费。3.不含垃圾清运。
A10: 6 | C10: 地下室混凝土墙体拆除 | E10: M2 | G10: 200 | H10: =F10*G10 -> 0 | I10: 1、拆除前客户签订免责协议。 2、人工费。3.不含垃圾清运。
A11: 7 | C11: 打单开门洞及门洞修边 | E11: 只 | G11: 200 | H11: =F11*G11 -> 0 | I11: 1、指不违反物业规定的非承重墙； 2、人工费； 3、水泥砂浆粉面抹灰。
A12: 8 | C12: 打双开门洞及门洞修边 | E12: 只 | G12: 300 | H12: =F12*G12 -> 0 | I12: 1、指不违反物业规定的非承重墙； 2、人工费； 3、水泥砂浆粉面抹灰。
A13: 9 | C13: 原门洞升高及门洞修边 | E13: 只 | G13: 200 | H13: =F13*G13 -> 0 | I13: 1、指不违反物业规定的非承重墙； 2、人工费； 3、水泥砂浆粉面抹灰。
A14: 10 | C14: 原有地梁拆除及修补 | E14: M | G14: 200 | H14: =F14*G14 -> 0 | I14: 1、人工费； 2、垃圾装袋运至小区指定点，如需要运到小区外费用另计。
A15: 11 | C15: 拆除原有管道井 | E15: M | G15: 50 | H15: =F15*G15 -> 0 | I15: 1、人工费； 2、垃圾装袋运至小区指定点，如需要运到小区外费用另计。
A16: 12 | C16: 原有飘窗拆除 | E16: M | G16: 360 | H16: =F16*G16 -> 0 | I16: 1、人工费； 2、垃圾装袋运至小区指定点，如需要运到小区外费用另计。 3、如遇混凝土及钢结构飘窗费用另计
A17: 13 | C17: 飘窗拆除后修补 | E17: 只 | G17: 300 | H17: =F17*G17 -> 0 | I17: 2.5米以内，不含拆除
A18: 14 | C18: 飘窗拆除后修补 | E18: 只 | H18: =F18*G18 -> 0 | I18: 3.5米以内，不含拆除
A19: 15 | C19: 原有现浇楼板拆除及修补 | E19: M2 | G19: 200 | H19: =F19*G19 -> 0 | I19: 1、人工费； 2、水泥砂浆粉面抹灰。
A20: 16 | C20: 混凝土楼梯拆除 | E20: 步 | G20: 180 | H20: =F20*G20 -> 0 | I20: 1、人工费； 2、垃圾装袋运至小区指定点，如需要运到小区外费用另计。
A21: 17 | C21: 构造梁拆除 | E21: M | G21: 100 | H21: =F21*G21 -> 0 | I21: 1、人工费； 2、垃圾装袋运至小区指定点，如需要运到小区外费用另计。
A22: 18 | C22: 拆除楼梯栏杆（护栏） | E22: M | G22: 15 | H22: =F22*G22 -> 0 | I22: 1、人工费；
A23: 19 | C23: 拆除楼梯过道水泥砌体 | E23: M | G23: 35 | H23: =F23*G23 -> 0 | I23: 1、人工费； 2、垃圾装袋运至小区指定点，如需要运到小区外费用另计。
A24: 20 | C24: 外墙砖拆除 | E24: M2 | G24: 78 | H24: =F24*G24 -> 0 | I24: 1、人工费； 2、垃圾装袋运至小区指定点，如需要运到小区外费用另计。
A25: 21 | C25: 常规瓷砖/石材拆除 | E25: M2 | G25: 30 | H25: =F25*G25 -> 0 | I25: 1、人工费； 2、垃圾装袋运至小区指定点，如需要运到小区外费用另计。
A26: 22 | C26: 外墙石材拆除/气割角铁 | E26: M2 | G26: 78 | H26: =F26*G26 -> 0 | I26: 1、人工费； 2、垃圾装袋运至小区指定点，如需要运到小区外费用另计。
A27: 23 | C27: 外墙涂料层铲除 | E27: M2 | G27: 30 | H27: =F27*G27 -> 0 | I27: 1、人工费； 2、垃圾装袋运至小区指定点，如需要运到小区外费用另计。
A28: 24 | C28: 墙壁柱面砂浆黏贴瓷砖/石材面层铲除 | E28: M2 | G28: 30 | H28: =F28*G28 -> 0 | I28: 1、人工费； 2、垃圾装袋运至小区指定点，如需要运到小区外费用另计。
A29: 25 | C29: 内墙顶涂料铲除及打毛处理 | E29: M2 | G29: 30 | H29: =F29*G29 -> 0 | I29: 1、人工费； 2、垃圾装袋运至小区指定点，如需要运到小区外费用另计。
A30: 26 | C30: 阳台地面垫层铲除 | E30: M2 | G30: 30 | H30: =F30*G30 -> 0 | I30: 1、人工费； 2、垃圾装袋运至小区指定点，如需要运到小区外费用另计。
... A36: 32 | C36: 装修建筑垃圾外运 | E36: 车 | G36: 500 | H36: =F36*G36 -> 0 | I36: 遇物业不负责垃圾外运时，装修所产生的建筑垃圾外运费用。
A37: 【二、楼梯项目】
A38: 1 | C38: 钢楼梯直跑踏步 | E38: 阶 | G38: 350 | H38: =F38*G38 -> 0 | I38: 12号槽钢，4号角钢，不含面层钢板制作（0.9米宽内）
A39: 2 | C39: 钢楼梯弧形踏步 | E39: 阶 | G39: 400 | H39: =F39*G39 -> 0 | I39: 12号槽钢，4号角钢，不含面层钢板制作（0.9米宽内）
A40: 3 | C40: 钢架楼梯转角踏步（45。） | E40: 阶 | G40: 600 | H40: =F40*G40 -> 0 | I40: 12号槽钢，4号角钢，不含面层钢板制作（0.9米宽内）
A41: 4 | C41: 钢架楼梯防锈漆 | E41: 阶 | G41: 30 | H41: =F41*G41 -> 0 | I41: 防锈漆涂刷。
A42: 5 | C42: 现浇钢筋混凝土直跑楼梯 | E42: 阶 | G42: 550 | H42: =F42*G42 -> 0 | I42: 1、支撑模板； 2、强度32.5普通硅酸盐水泥； 3、12mm钢材交错预埋； 4、混凝土浇筑； 5、如需槽钢加固或浇筑大梁的需另加费用。 6、（0.9米宽内）
A43: 6 | C43: 现浇钢筋混凝土直跑楼梯转角踏步平台 | E43: 阶 | G43: 700 | H43: =F43*G43 -> 0 | I43: 1、支撑模板； 2、强度32.5普通硅酸盐水泥； 3、12mm钢材交错预埋； 4、混凝土浇筑； 5、如需槽钢加固或浇筑大梁的需另加费用。 6、（0.10米宽内）
A44: 7 | C44: 现浇钢筋混凝土弧形楼梯 | E44: 阶 | G44: 780 | H44: =F44*G44 -> 0 | I44: 1、支撑模板； 2、强度32.5普通硅酸盐水泥； 3、12mm钢材交错预埋； 4、混凝土浇筑； 5、如需槽钢加固或浇筑大梁的需另加费用。 6、（0.9米宽内）
A45: 8 | C45: 楼梯踏步基层（900mm） | E45: 阶 | G45: 70 | H45: =F45*G45 -> 0 | I45: 防锈漆涂刷。
A46: 9 | C46: 楼梯踏步基层（1200mm） | E46: 阶 | G46: 80 | H46: =F46*G46 -> 0 | I46: 木工板+九厘板侧板
...

Sheet 墙面
A2: 【一、墙面工程】
A3: 编号 | C3: 工程项目 | E3: 单位 | F3: 数量 | I3: 备 注
G4: 山屿单价 | H4: 金额
A5: 1 | C5: 墙面归方找平 | E5: M2 | G5: 88 | H5: =F5*G5 -> 0 | I5: 外框*88一平（人工加材料）
A6: 2
A7: 3 | C7: 墙面基层处理 | E7: M2 | G7: 42 | H7: =F7*G7 -> 0 | I7: 1、刷界面剂一遍，批刮腻子三遍，打磨平整； 2、顶面水泥砂浆处理、沙灰墙铲除、原顶面涂层铲除及贴布等费用另计； 3、原顶面平整度误差超过1.5cm、垂直误差超过1.5cm需找平，费用另计。
A8: 4 | C8: 墙面乳胶漆 | E8: M2 | G8: 13 | H8: =F8*G8 -> 0 | I8: 1、一遍底涂 2、两遍面涂及人工。
A9: 5 | C9: PVC常规型阴阳角线 | E9: M2 | G9: 8 | H9: =F9*G9 -> 0 | I9: 1、专业阴阳角线条处理。 2、按内墙面积计算
A10: 6 | C10: 线型灯修补 | E10: M | G10: 15 | H10: =F10*G10 -> 0 | I10: 主材甲购，商家安装，油漆修补人工费
A11: 7 | C11: 原墙面墙皮铲除 | E11: M2 | G11: 8 | H11: =F11*G11 -> 0 | I11: 1、室内原墙面水性涂层铲除； 2、非亲水性涂层铲除费用另计。
A12: 8 | C12: 1200*2400mm岩板（胶泥粘帖） | E12: M2 | F12: 0 | G12: 300 | H12: =F12*G12 -> 0 | I12: 1、轻工辅料， 2、马贝胶泥铺贴；
A13: 9 | C13: 900*1800mm墙砖（胶泥粘帖） | E13: M2 | F13: 0 | G13: 220 | H13: =F13*G13 -> 0 | I13: 1、轻工辅料， 2、马贝胶泥铺贴；
A14: 10 | C14: 1500*750mm墙砖 | E14: M2 | G14: 180 | H14: =F14*G14 -> 0 | I14: 1、轻工辅料， 2、胶泥铺贴；
A15: 11 | C15: 1200*600mm墙砖 | E15: M2 | G15: 170 | H15: =F15*G15 -> 0 | I15: 1、轻工辅料， 2、胶泥铺贴；
A16: 12 | C16: 400*800mm墙砖 | E16: M2 | G16: 150 | H16: =F16*G16 -> 0 | I16: 1、轻工辅料， 2、德高/雨虹胶泥铺贴；
A17: 13 | C17: ≤200*200mm墙砖以内 | E17: M2 | G17: 200 | H17: =F17*G17 -> 0 | I17: 1、轻工辅料， 2、胶泥铺贴；
A18: 14 | C18: 多规格莱姆石铺贴 | E18: M2 | G18: 200 | H18: =F18*G18 -> 0 | I18: 1、轻工辅料， 2、胶泥铺贴；
A19: 15 | C19: 墙面（薄贴）增加费 | E19: M2 | G19: 20 | H19: =F19*G19 -> 0 | I19: 墙面（薄贴）瓷砖增加费
A20: 16 | C20: 墙面（斜铺）瓷砖增加费 | E20: M2 | G20: 20 | H20: =F20*G20 -> 0 | I20: 墙面（斜铺）瓷砖增加费
A21: 17 | C21: 墙面（错缝、拼花、不规则铺贴）瓷砖增加费 | E21: M2 | G21: 40 | H21: =F21*G21 -> 0 | I21: 墙面（错缝、拼花、不规则铺贴）瓷砖增加费
A22: 18 | C22: 腰线铺贴增加 | E22: M | G22: 20 | H22: =F22*G22 -> 0 | I22: 人工费
A23: 19 | C23: 壁龛工艺增加 | E23: 项 | G23: 499 | H23: =F23*G23 -> 0 | I23: 水泥黄沙浇筑，贴砖工艺人工费
A24: 20 | C24: 墙面马赛克粘贴 | E24: M2 | G24: 200 | H24: =F24*G24 -> 0 | I24: 1、轻工辅料，马赛克由客户提供； 2、水泥砂浆粉平整，胶泥{或玻璃胶}铺贴，填缝剂甲供
A25: 21 | C25: 墙面水性防水涂料（地暖地面要算2遍） | E25: M2 | G25: 65 | H25: =F25*G25 -> 0 | I25: 1、墙面清理，涂刷水性防水涂料2遍； 2、卫生间墙面涂刷1800mm； 3、做24小时蓄水试验（甲方验收签字）； 4、不包含原地面装饰层拆除； 5、按实际涂刷面积计算工程量。

Sheet 顶面
A2: 【一、顶面工程】
A3: 编号 | C3: 工程项目 | E3: 单位 | F3: 数量 | I3: 备 注
G4: 山屿单价 | H4: 金额
A5: 1 | C5: 双层石膏板吊顶（用于拐角/风口） | E5: M2 | G5: 258 | H5: =F5*G5 -> 0 | I5: 1、轻钢骨架，间距一般为400mm,打孔下膨胀螺栓固定； 2、9.5mm厚纸面石膏板罩面，加欧松板自攻螺丝钉固定，钉眼点涂防锈漆，石膏板接缝处填嵌石膏，粘帖专用绷带；
A6: 2 | C6: 双层石膏板墙面找平 | E6: M2 | G6: 188 | H6: =F6*G6 -> 0 | I6: 墙面木楔找平
A7: 3 | C7: 欧松板打底 | E7: M2 | G7: 138 | H7: =F7*G7 -> 0 | I7: 1、轻钢骨架，间距一般为400mm,打孔下膨胀螺栓固定； 2、12/15mm欧松板打底
A8: 4 | C8: 欧松板基层石膏板饰面 | E8: M2 | G8: 240 | H8: =F8*G8 -> 0 | I8: 1、轻钢骨架，间距一般为400mm,打孔下膨胀螺栓固定； 2、12/15mm欧松板打底 95mm石膏板
A9: 5 | C9: 顶面基层处理 | E9: M2 | G9: 47 | H9: =F9*G9 -> 0 | I9: 1、刷界面剂一遍，批刮腻子三遍，打磨平整； 2、顶面水泥砂浆处理、沙灰墙铲除、原顶面涂层铲除及贴布等费用另计； 3、原顶面平整度误差超过1.5cm、垂直误差超过1.5cm需找平，费用另计。
A10: 6 | C10: 顶面乳胶漆 | E10: M2 | G10: 18 | H10: =F10*G10 -> 0 | I10: 1、一遍底涂 2、两遍面涂及人工。
A11: 7 | C11: 吊顶石膏板接缝、干壁钉防锈处理 | E11: M2 | G11: 5 | H11: =F11*G11 -> 0 | I11: 1、接缝纸接石膏板接缝、干壁钉防锈漆处理。 2、按吊顶面积计算
A12: 8 | C12: 顶面基层处理(防水腻子） | E12: M2 | G12: 58 | H12: =F12*G12 -> 0 | I12: 1、刷界面剂一遍，批刮腻子三遍，打磨平整； 2、顶面水泥砂浆处理、沙灰墙铲除、原顶面涂层铲除及贴布等费用另计； 3、原顶面平整度误差超过1.5cm、垂直误差超过1.5cm需找平，费用另计。
A13: 9 | C13: 顶面防水乳胶漆 | E13: M2 | G13: 28 | H13: =F13*G13 -> 0 | I13: 1、一遍底涂 2、两遍面涂及人工。
A14: 10 | C14: 线型灯修补 | E14: M | H14: =F14*G14 -> 0 | I14: 油漆修补人工费
A15: 11
A16: 12 | C16: 原顶面墙皮铲除 | E16: M2 | G16: 8 | H16: =F16*G16 -> 0 | I16: 1、室内原顶面水性涂层铲除； 2、非亲水性涂层铲除费用另计。
A17: 13 | C17: 石膏板吊平顶 | E17: M2 | G17: 168 | H17: =F17*G17 -> 0 | I17: 1、轻钢骨架，间距一般为400mm,打孔下膨胀螺栓固定； 2、9.5mm厚纸面石膏板罩面，自攻螺丝钉固定，钉眼点涂防锈漆，石膏板接缝处填嵌石膏，粘帖专用绷带；
A18: 14 | C18: 石膏板异性造型吊顶 | E18: M2 | G18: 258 | H18: =F18*G18 -> 0 | I18: 1、轻钢骨架，间距一般为400mm,打孔下膨胀螺栓固定； 2、9.5mm厚纸面石膏板罩面，自攻螺丝钉固定，钉眼点涂防锈漆，石膏板接缝处填嵌石膏，粘帖专用绷带；
A19: 15 | C19: 圆形造型费 | E19: 项 | G19: 800 | H19: =F19*G19 -> 0 | I19: 根据尺寸决定，长度不超过2.4米
A20: 16 | C20: 石膏板普通单层边吊（≤300mm） | E20: M2 | G20: 208 | H20: =F20*G20 -> 0 | I20: 1、轻钢骨架，间距一般为400mm,打孔下膨胀螺栓固定； 2、9.5mm厚纸面石膏板罩面，自攻螺丝钉固定，钉眼点涂防锈漆，石膏板接缝处填嵌石膏，粘帖专用绷带； 3、宽度不大于60mm。
A21: 17 | C21: 石膏板单级走边（≤200mm） | E21: M | G21: 80 | H21: =F21*G21 -> 0 | I21: 木板基层，石膏板封边，宽度少于20mm
A22: 18 | C22: 石膏板双级走边/双眼皮走边 | E22: M | G22: 100 | H22: =F22*G22 -> 0 | I22: 木板基层，石膏板封边，宽度少于20mm
A23: 19 | C23: 吊顶凹槽造型/线型灯 | E23: M | G23: 50 | H23: =F23*G23 -> 0 | I23: 留槽工艺
A24: 20 | C24: 空调出风或回风口框架 | E24: M | G24: 200 | H24: =F24*G24 -> 0 | I24: 松木档框架，长度≤2000mm（双层石膏板）
A25: 21 | C25: 窗帘盒 | E25: M | G25: 208 | H25: =F25*G25 -> 0 | I25: 1、优等欧松板做底板与立板，石膏板贴面，外面批腻子、刷漆； 2、宽度≤280mm； 3、此为一般形式的做法，特殊做法具体情况确定。
A26: 22 | C26: 反光灯槽吊顶 | E26: M | G26: 60 | H26: =F26*G26 -> 0 | I26: 木工板基层，石膏板封边
A27: 23 | C27: 防水石膏板吊平顶 | E27: M2 | G27: 268 | H27: =F27*G27 -> 0 | I27: 1、轻钢骨架，间距一般为400mm,打孔下膨胀螺栓固定；预埋检修口 2、9.5mm厚纸面石膏板罩面，自攻螺丝钉固定，钉眼点涂防锈漆，石膏板接缝处填嵌石膏，粘帖专用绷带；
... A33: 29 | C33: 石膏板吊顶 三级弧线造型顶 | E33: M | G33: 338 | H33: =F33*G33 -> 0 | I33: 1、轻钢骨架，间距一般为400mm,打孔下膨胀螺栓固定； 2、9.5mm厚纸面石膏板罩面，自攻螺丝钉固定，钉眼点涂防锈漆，石膏板接缝处填嵌石膏，粘帖专用绷带； 3、立面可使用一级5厘板或双层3厘板； 4、按展开面积计算工程量。 5、此为基础价格，对造型较复杂的吊顶，视具体情况确定。
A34: 30 | C34: 石膏板吊顶 灯池直线一级造型顶 | E34: M | H34: =F34*G34 -> 0 | I34: 1、木龙骨骨架，间距一般为400mm,打孔下膨胀螺栓固定； 2、9.5mm厚纸面石膏板罩面，自攻螺丝钉固定，钉眼点涂防锈漆，石膏板接缝处填嵌石膏，粘帖专用绷带； 3、若改用防水石膏板，价格另加30元/M2。
A35: 31 | C35: 石膏板吊顶 灯池直线二级造型顶 | E35: M | H35: =F35*G35 -> 0 | I35: 1、木龙骨骨架，间距一般为400mm,打孔下膨胀螺栓固定； 2、9.5mm厚纸面石膏板罩面，自攻螺丝钉固定，钉眼点涂防锈漆，石膏板接缝处填嵌石膏，粘帖专用绷带； 3、若改用防水石膏板，价格另加30元/M2。
A36: 32 | C36: 石膏板吊顶 灯池直线三级造型顶 | E36: M | H36: =F36*G36 -> 0 | I36: 1、木龙骨骨架，间距一般为400mm,打孔下膨胀螺栓固定； 2、9.5mm厚纸面石膏板罩面，自攻螺丝钉固定，钉眼点涂防锈漆，石膏板接缝处填嵌石膏，粘帖专用绷带； 3、若改用防水石膏板，价格另加30元/M2。
A37: 33 | C37: 石膏板吊顶 灯池一级弧线造型顶 | E37: M | H37: =F37*G37 -> 0 | I37: 1、轻钢骨架，间距一般为400mm,打孔下膨胀螺栓固定； 2、9mm厚纸面石膏板罩面，自攻螺丝钉固定，钉眼点涂防锈漆，石膏板接缝处填嵌石膏，粘帖专用绷带； 3、立面可使用一级5厘板或双层3厘板； 4、按展开面积计算工程量。 5、此为基础价格，对造型较复杂的吊顶，视具体情况确定。
A38: 34 | C38: 石膏板吊顶 灯池二级弧线造型顶 | E38: M | H38: =F38*G38 -> 0 | I38: 1、轻钢骨架，间距一般为400mm,打孔下膨胀螺栓固定； 2、9.5mm厚纸面石膏板罩面，自攻螺丝钉固定，钉眼点涂防锈漆，石膏板接缝处填嵌石膏，粘帖专用绷带； 3、立面可使用一级5厘板或双层3厘板； 4、按展开面积计算工程量。 5、此为基础价格，对造型较复杂的吊顶，视具体情况确定。
A39: 35 | C39: 石膏板吊顶 灯池三级弧线造型顶 | E39: M | H39: =F39*G39 -> 0 | I39: 1、轻钢骨架，间距一般为400mm,打孔下膨胀螺栓固定； 2、9.5mm厚纸面石膏板罩面，自攻螺丝钉固定，钉眼点涂防锈漆，石膏板接缝处填嵌石膏，粘帖专用绷带； 3、立面可使用一级5厘板或双层3厘板； 4、按展开面积计算工程量。 5、此为基础价格，对造型较复杂的吊顶，视具体情况确定。
A40: 36 | C40: 弧形石膏线角花（80mm以内） | E40: 个 | G40: 135 | H40: =F40*G40 -> 0 | I40: 石膏阴角线角花，专用胶粉粘帖，含修补
A41: 37 | C41: 弧形石膏线开模费 | E41: 个 | G41: 1000 | H41: =F41*G41 -> 0 | I41: 100mm-200mm开模费500元/个,200mm-280mm开模费600元/个

Sheet 地面
A2: 【一、地面工程】
A3: 编号 | C3: 工程项目 | E3: 单位 | F3: 数量 | I3: 备 注
G4: 山屿单价 | H4: 金额
A5: 1 | C5: 地面瓷砖波导线 | E5: M | H5: =F5*G5 -> 0 | I5: 1、人工； 2、放样，铺贴； 3、不含踢脚线安装。（如果需要勾缝，送勾缝，勾缝剂由客户提供）
A6: 2 | C6: 400*400mm地砖（水泥砂浆粘贴） | E6: M2 | G6: 140 | H6: =F6*G6 -> 0 | I6: 水泥黄沙铺贴，斜铺、错缝、不规则、走边铺贴费用另计，不含美缝。
A7: 3 | C7: 800*800mm地砖（水泥砂浆粘贴） | E7: M2 | G7: 150 | H7: =F7*G7 -> 0 | I7: 水泥黄沙铺贴，斜铺、错缝、不规则、走边铺贴费用另计，不含美缝。
A8: 4 | C8: 600*1200mm地砖（水泥砂浆粘贴） | E8: M2 | G8: 160 | H8: =F8*G8 -> 0 | I8: 水泥黄沙铺贴，斜铺、错缝、不规则、走边铺贴费用另计，不含美缝。
A9: 5 | C9: 750*1500mm地砖（水泥砂浆粘贴） | E9: M2 | G9: 180 | H9: =F9*G9 -> 0 | I9: 水泥黄沙铺贴，斜铺、错缝、不规则、走边铺贴费用另计，不含美缝。
A10: 6 | C10: 900*1800mm地砖（水泥砂浆粘贴） | E10: M2 | F10: 0 | G10: 200 | H10: =F10*G10 -> 0 | I10: 水泥黄沙铺贴，斜铺、错缝、不规则、走边铺贴费用另计，不含美缝、胶泥。
A11: 7 | C11: ≤70*300mm地砖（水泥砂浆粘贴 | E11: M2 | G11: 230 | H11: =F11*G11 -> 0 | I11: 水泥黄沙铺贴，斜铺、错缝、不规则、走边铺贴费用另计，不含美缝。
A12: 8 | C12: 地面瓷砖增加费（斜铺） | E12: M2 | G12: 20 | H12: =F12*G12 -> 0 | I12: 1、（斜铺）瓷砖增加费，仅增加计算（斜铺）实际施工面积； 2、按图案设计拼贴等。
A13: 9 | C13: 地面（薄贴）瓷砖增加人工费 | E13: M2 | G13: 20 | H13: =F13*G13 -> 0 | I13: 地面（薄贴）增加费
A14: 10 | C14: 地面瓷砖增加费（错缝、拼花、不规则铺贴） | E14: M2 | G14: 40 | H14: =F14*G14 -> 0 | I14: 1、（斜铺、错缝、拼花、不规则铺贴）瓷砖增加费，仅增加计算（斜铺、错缝、拼花、不规则铺贴）实际施工面积； 2、按图案设计拼贴等。
A15: 11 | C15: 地面马赛克粘贴 | E15: M2 | G15: 220 | H15: =F15*G15 -> 0 | I15: 1、轻工辅料； 2、水泥砂浆粉平整，胶泥{或玻璃胶}铺贴，填缝剂甲供
A16: 12 | C16: 石材窗台板铺设 | E16: M | G16: 100 | H16: =F16*G16 -> 0 | I16: 1、轻工辅料，宽度≤300mm; 2、干性水泥砂浆铺贴，玻璃胶填缝； 3、不含抛光打蜡。
A17: 13 | C17: 石材窗台板铺设（飘窗） | E17: M | G17: 155 | H17: =F17*G17 -> 0 | I17: 1、轻工辅料，，宽度≤800mm; 2、干性水泥砂浆铺贴，玻璃胶填缝； 3、不含抛光打蜡。
A18: 14 | C18: 地面翻边铺贴 | E18: M | G18: 183 | H18: =F18*G18 -> 0 | I18: 水泥砂浆铺贴，总宽度≤450
A19: 15 | C19: 门槛石、挡水条安装 | E19: 条 | G19: 120 | H19: =F19*G19 -> 0 | I19: 水泥黄沙铺贴
A20: 16 | C20: 地面水性防水涂料（地暖地面要算2遍） | E20: M2 | G20: 65 | H20: =F20*G20 -> 0 | I20: 1、地面清理，涂刷水性防水涂料2遍； 2、一般墙面上返300mm。 3、做24小时蓄水试验（甲方验收签字）； 4、不包含原地面装饰层拆除； 5、按实际涂刷面积计算工程量。
A21: 17 | C21: 木制地台（一级细木工板） | E21: M2 | G21: 208 | H21: =F21*G21 -> 0 | I21: 1、松木方或优等细木工板开条做骨架，上铺优等细木工板，抽屉另计； 2、地板、地毯、石塑等面层铺设另计； 3、按平面面积计算工程量，高度≤200mm。
A22: 18 | C22: 瓷砖踢脚线 | E22: M | G22: 30.5 | H22: =F22*G22 -> 0 | I22: 1、清工辅料，瓷砖踢脚线由客户提供； 2、墙面清理，用强度32.5普通硅酸盐水泥、中砂水泥砂浆镶贴； 3、如用专业粘结剂和专用勾缝剂，甲供。
A23: 19 | C23: 地面精找平 | E23: M2 | F23: 0 | G23: 78 | H23: =F23*G23 -> 0 | I23: 水泥黄沙瓜子片精找平（平铺地板/地砖博贴专用，误差3mm）（厚度3cm）
A24: 20 | C24: 粗找平 | E24: M2 | F24: 0 | G24: 58 | H24: =F24*G24 -> 0 | I24: 水泥黄沙瓜子片找平垫层，厚度≤50cm
A25: 21 | C25: 半干砂浆找平 | E25: M2 | F25: 0 | G25: 98 | H25: =F25*G25 -> 0 | I25: 半干砂浆找平（增加马贝sp700增强乳液）误差3毫米
A26: 22 | C26: 地坪打磨修补 | E26: M2 | G26: 40 | H26: =F26*G26 -> 0 | I26: 含固化

Sheet 水电 
A2: 【水电工程】
A3: 编号 | C3: 工程项目 | E3: 单位 | F3: 数量 | G3: 工 程 造 价 | I3: 备 注
G4: 单价 | H4: 金额
A5: 保利、正泰
A6: 1 | C6: 开管线槽 | E6: M2 | F6: 0 | G6: 15.5 | H6: =F6*G6 -> 0 | I6: 1 切割片 垃圾袋。
A7: 2 | C7: 打孔穿线 | E7: M2 | F7: 0 | G7: 15.5 | H7: =F7*G7 -> 0 | I7: 1 人工费 垃圾袋。
A8: 3 | C8: 给水工程（PPR） | E8: M2 | F8: 0 | G8: 70 | H8: =F8*G8 -> 0 | I8: 1、【保利橙色管25直径，壁厚4.2】ppr水管热熔连接； 2、开槽、定位； 3、冷热水管EVA保温防潮工艺（顶面走向）
A9: 4 | C9: 排水工程（PVC） | E9: M2 | F9: 0 | G9: 33.5 | H9: =F9*G9 -> 0 | I9: 保利PVC排水管、定位.
A10: 5 | C10: 强电工程（1.5；2.5BV线；4.0Bvr线） | E10: M2 | F10: 0 | G10: 74.8 | H10: =F10*G10 -> 0 | I10: 【保利橙色管25直径，壁厚4.2】PVC穿线管、【正泰】高阻燃电线、86底盒、定位.
A11: 6 | C11: 弱电工程（6类网线，电视线） | E11: M2 | F11: 0 | G11: 10.7 | H11: =F11*G11 -> 0 | I11: 【保利橙色管25直径，壁厚4.2】PVC穿线管、【正泰】高阻燃电线、86底盒、定位.
A12: 保利、普瑞斯曼（c型钢工艺）
A13: 1 | C13: 开管线槽 | E13: M2 | F13: 0 | G13: 15.5 | H13: =F13*G13 -> 0 | I13: 1 切割片 垃圾袋。
A14: 2 | C14: 打孔穿线 | E14: M2 | F14: 0 | G14: 15.5 | H14: =F14*G14 -> 0 | I14: 1 人工费 垃圾袋。
A15: 3 | C15: 给水工程（PPR） | E15: M2 | F15: 0 | G15: 120 | H15: =F15*G15 -> 0 | I15: 1、【保利橙色管25直径，壁厚4.2】ppr水管热熔连接； 2、开槽、定位； 3、冷热水管EVA保温防潮工艺（顶面走向）
A16: 4 | C16: 排水工程（PVC） | E16: M2 | F16: 0 | G16: 33.5 | H16: =F16*G16 -> 0 | I16: 保利PVC排水管、定位.
A17: 5 | C17: 强电工程（1.5；2.5BV线；4.0Bvr线） | E17: M2 | F17: 0 | G17: 104.8 | H17: =F17*G17 -> 0 | I17: 【保利橙色管25直径，壁厚4.2】PVC穿线管、【普瑞斯曼】高阻燃电线、86底盒、定位.
A18: =A17+1 -> 6 | C18: 弱电工程（6类网线，电视线） | E18: M2 | F18: 0 | G18: 30.7 | H18: =F18*G18 -> 0 | I18: 【保利橙色管25直径，壁厚4.2】PVC穿线管、【普瑞斯曼】高阻燃电线、86底盒、定位.
A19: 【安装工程】
A20: 6 | C20: 跃层施工费 | E20: 层 | F20: 0 | G20: 1200 | H20: =SUM(F20*G20) -> 0 | I20: 跃层施工费
A21: 7 | C21: 照明安装 | E21: M2 | F21: 0 | G21: 5 | H21: =SUM(F21*G21) -> 0 | I21: 普通套房照明灯安装。吊灯除外
A22: 8 | C22: 开关面板安装 | E22: M2 | F22: 0 | G22: 5 | H22: =SUM(F22*G22) -> 0 | I22: 人工费,不含主材（单层≤150m2）
A23: 9 | C23: 强电箱移位 | E23: 只 | F23: 0 | G23: 785 | H23: =F23*G23 -> 0 | I23: 含PVC管、开槽，敷设人工,含箱子
A24: 10 | C24: 弱电箱移位 | E24: 只 | F24: 0 | G24: 585 | H24: =F24*G24 -> 0 | I24: 含PVC管、开槽，敷设人工,含箱子
A25: 11 | C25: 卫生间排污管移位 | E25: 项 | F25: 0 | G25: 180 | H25: =SUM(F25*G25) -> 0 | I25: PVC移位器、排管、人工。
A26: 12 | C26: 下沉卫生间下水改造 | E26: 间 | F26: 0 | G26: 450 | H26: =SUM(F26*G26) -> 0 | I26: PVC排水管、定位.
A27: 13 | C27: 空开更换 | E27: M2 | F27: 0 | G27: 8 | H27: =SUM(F27*G27) -> 0 | I27: 正泰（含总开、漏电保护器、空开，单个电箱配置）按建筑面积计算
A28: 14 | C28: 空开更换 | E28: M2 | F28: 0 | G28: 20 | H28: =SUM(F28*G28) -> 0 | I28: 施耐德（含总开、漏电保护器、空开，单个电箱配置）按建筑面积计算
A29: 15 | C29: 增加一路热水器布管 | E29: 项 | F29: 0 | G29: 651 | H29: =SUM(F29*G29) -> 0 | I29: 太阳能、电热水器、空气源、即热式电热水器布线
A30: 16 | C30: 大热水循环水布管 | E30: M2 | F30: 0 | G30: 35 | H30: =SUM(F30*G30) -> 0 | I30: 按建筑面积外框计算
A31: 17 | C31: 软水系统管道铺设 | E31: 间 | F31: 0 | G31: 942 | H31: =SUM(F31*G31) -> 0 | I31: 1、PP-R管，热熔连接2、热水管管道保温防潮处理
A32: 18 | C32: 分水器布管 | E32: M2 | F32: 0 | G32: 32.5 | H32: =SUM(F32*G32) -> 0 | I32: 按建筑面积外框计算（4路内）法兰特工艺
A33: 19 | C33: 卫生间五金安装 | E33: 间 | F33: 0 | G33: 200 | H33: =SUM(F33*G33) -> 0 | I33: 人工费,不含主材
A34: 20 | C34: 龙头 洁具安装 | E34: 间 | F34: 0 | G34: 200 | H34: =SUM(F34*G34) -> 0 | I34: 厨房、卫生间龙头、洁具安装(淋浴房厂家安装)
A35: 21 | C35: 冷热水管保温处理 | E35: M2 | F35: 0 | G35: 4 | H35: =SUM(F35*G35) -> 0 | I35: 1、PP-R热水管套保温管，含材料及人工（建筑面积计算）
A36: 22 | C36: 下水管隔音处理（卫生间） | E36: 间 | F36: 0 | G36: 220 | H36: =SUM(F36*G36) -> 0 | I36: 1、卫生间下水做隔音处理，含材料及人工
A37: 23 | C37: 油烟机管道铺设 | E37: M | F37: 0 | G37: 120 | H37: =SUM(F39*G37) -> 0 | I37: 110PVC管
A38: 24 | C38: 风管机/中央空调外机强电穿线 | E38: 项 | F38: 0 | G38: 480 | H38: =SUM(F38*G38) -> 0 | I38: 1、国标单芯铜线 2、PVC阻燃双色线管开槽铺设安装（4-6平方布线）
A39: 25 | C39: 风管机/中央空调外机强电穿线 | E39: M | F39: 0 | G39: 10 | H39: =SUM(F39*G39) -> 0 | I39: 1、国标单芯铜线 2、PVC阻燃双色线管开槽铺设安装
A40: 26 | C40: 音频弱电布置 | E40: 路 | F40: 0 | G40: 200 | H40: =SUM(F40*G40) -> 0 | I40: 1、全铜音频线 2、PVC阻燃双色线管开槽铺设安装 3、国标86通用型暗盒 4、透明暗盒保护盖防护 5、进口电线保护帽保护
A41: 27 | C41: 监控布线 | E41: 路 | F41: 0 | G41: 200 | H41: =SUM(F41*G41) -> 0 | I41: 1、超五类8芯双绞线 2、PVC阻燃双色线管开槽铺设安装 3、国标86通用型暗盒 4、透明暗盒保护盖防护 5、进口电线保护帽保护
...

Sheet 其他
A2: 【一、其他工程】
A3: 编号 | C3: 工程项目 | E3: 单位 | F3: 数量 | I3: 备 注
G4: 山屿单价 | H4: 金额
A5: 1 | C5: 安装开关面板插座 | E5: M2 | G5: 5 | H5: =F5*G5 -> 0 | I5: 安装（不含空调、地暖控制器和门禁系统、安防系统、智能系统等的安装）
A6: 2 | C6: 安装开关面板插座 别墅、联排及240㎡以上的复式、平层 | E6: M2 | G6: 8 | H6: =F6*G6 -> 0 | I6: 安装（不含空调、地暖控制器和门禁系统、安防系统、智能系统等的安装）
A7: 3 | C7: 灯具安装（三居室以下） | E7: 项 | G7: 600 | H7: =F7*G7 -> 0 | I7: 1、包括室内筒灯、室内牛眼灯、室内射灯、室内壁灯、室内吸顶灯、室内日光灯、室内灯带安装； 2、按照产品要求接线、安装； 3、不含插座、开关面板及其他安装； 4、顶棚使用螺栓固定，接线安装； 5、水晶灯、吊灯、线性灯等和800元以上的灯具必须由厂家安装，乙方不负责任安装。
A8: 4 | C8: 灯具安装（四居室） | E8: 项 | G8: 800 | H8: =F8*G8 -> 0 | I8: 1、包括室内筒灯、室内牛眼灯、室内射灯、室内壁灯、室内吸顶灯、室内日光灯、室内灯带安装； 2、按照产品要求接线、安装； 3、不含插座、开关面板及其他安装； 4、顶棚使用螺栓固定，接线安装； 5、水晶灯、吊灯、线性灯等和800元以上的灯具必须由厂家安装，乙方不负责任安装。
A9: 5 | C9: 灯具安装（四居室以上） | E9: 项 | G9: 1000 | H9: =F9*G9 -> 0 | I9: 1、包括室内筒灯、室内牛眼灯、室内射灯、室内壁灯、室内吸顶灯、室内日光灯、室内灯带安装； 2、按照产品要求接线、安装； 3、不含插座、开关面板及其他安装； 4、顶棚使用螺栓固定，接线安装； 5、水晶灯、吊灯、线性灯等和800元以上的灯具必须由厂家安装，乙方不负责任安装。
A10: 6 | C10: 灯具安装 别墅、联排及240㎡以上的复式、平层 | E10: 项 | G10: 2500 | H10: =F10*G10 -> 0 | I10: 1、包括室内筒灯、室内牛眼灯、室内射灯、室内壁灯、室内吸顶灯、室内日光灯、室内灯带安装； 2、按照产品要求接线、安装； 3、不含插座、开关面板及其他安装； 4、顶棚使用螺栓固定，接线安装； 5、水晶灯、吊灯、线性灯等和800元以上的灯具必须由厂家安装，乙方不负责任安装。
A11: 7 | C11: 台盆柜安装 | E11: 套 | G11: 150 | H11: =F11*G11 -> 0 | I11: 人工费
A12: 8 | C12: 卫浴挂件安装 | E12: 套 | G12: 250 | H12: =F12*G12 -> 0 | I12: 人工费（一个卫生间算一套）
A13: 9 | C13: 浴缸安装 带裙边 | E13: 只 | G13: 660 | H13: =F13*G13 -> 0 | I13: 人工费 黄沙 水泥 红砖
A14: 10 | C14: 网购灯具主灯安装（水晶灯不安装） | E14: 套 | G14: 300 | H14: =F14*G14 -> 0 | I14: 一层300元，以此类推。
A15: 11 | C15: 高档龙头/坐便器暗埋安装 | E15: 个 | G15: 350 | H15: =F15*G15 -> 0 | I15: 1、人工费。 2、只负责安装，若有损坏不负责赔偿。
A16: 15 | C16: 高档坐便器/淋浴龙头安装 | E16: 个 | G16: 200 | H16: =F16*G16 -> 0 | I16: 1、人工费。 2、只负责安装，若有损坏不负责赔偿。
... A22: 28 | C22: 成品保护 | E22: M2 | G22: 15 | H22: =F22*G22 -> 0 | I22: 乙方提供成品保护材料对于施工完成的半成品及成品进行保护。
A23: 29 | C23: 室内开荒保洁 | E23: M2 | G23: . | H23: =F23*G23 -> #VALUE! | I23: 完工时对工地进行室内家政服务。
A24: 30 | C24: 脚手架使用费（跃层中空部分) | E24: M2 | G24: 20 | H24: =F24*G24 -> 0 | I24: 中空部分，层高超过3.6米。
A25: 31 | C25: 脚手架使用费（别墅 排屋）240-300平方 | E25: 项 | G25: 2000 | H25: =F25*G25 -> 0 | I25: 室内脚手架费用。
A26: 32 | C26: 脚手架使用费（别墅 排屋）301-500平方 | E26: 项 | G26: 3000 | H26: =F26*G26 -> 0 | I26: 室内脚手架费用。
A27: 33 | C27: 脚手架使用费（别墅 排屋）501-700平方 | E27: 项 | G27: 4000 | H27: =F27*G27 -> 0 | I27: 室内脚手架费用。
A28: 34 | C28: 脚手架使用费（别墅 排屋）701-900平方 | E28: 项 | G28: 5000 | H28: =F28*G28 -> 0 | I28: 室内脚手架费用。
A29: 35 | C29: 脚手架使用费（别墅 排屋）901-1100平方 | E29: 项 | G29: 10000 | H29: =F29*G29 -> 0 | I29: 有游泳池的另加8000元。

Sheet 主材 卫浴
A2: 【四、马桶】
A3: 1 | C3: 普通虹吸式马桶 | E3: 个 | G3: 1200 | H3: =F3*G3 -> 0 | I3: 法恩莎家用虹吸式马桶
A4: 2 | C4: 轻智能马桶 | E4: 个 | G4: 2200 | H4: =F4*G4 -> 0 | I4: 法恩莎家用轻智能马桶
A5: 3 | C5: 全智能马桶 | E5: 个 | G5: 4000 | H5: =F5*G5 -> 0 | I5: 法恩莎家用全智能马桶（不带水箱）
A6: 4 | C6: 墙排马桶 | E6: 个 | G6: 4000 | H6: =F6*G6 -> 0 | I6: 法恩莎壁挂马桶（普通马桶）
A7: 5 | C7: 杜拉维特马桶 | E7: 个 | G7: 4000 | H7: =F7*G7 -> 0 | I7: 杜拉维特轻智能马桶60006系列
A8: 5 | C8: 汉斯格雅马桶 | E8: 个 | G8: 4500 | H8: =F8*G8 -> 0 | I8: 汉斯格雅轻智能马桶22478007系列
A9: 5 | C9: 蹲便器 | E9: 个 | G9: 1000 | H9: =F9*G9 -> 0 | I9: 法恩莎/含水箱
A10: 6 | C10: 小便斗 | E10: 个 | G10: 1200 | H10: =F10*G10 -> 0 | I10: 法恩莎，开槽打孔安装
A11: 7 | C11: 轻智能马桶 | E11: 个 | G11: 3599 | H11: =F11*G11 -> 0 | I11: 科勒家用轻智能马桶
A12: 【五、浴室柜】
A13: 1 | C13: 德利丰免漆浴室柜 | E13: 米 | G13: 4500 | H13: =F13*G13 -> 0 | I13: 德利丰岩板台面,定制镜柜，免漆柜体，科勒陶瓷盆（按米收费）（德利丰大板可选）（不含龙头）
A14: 1 | C14: 德利丰烤漆浴室柜 | E14: 米 | G14: 6500 | H14: =F14*G14 -> 0 | I14: 德利丰岩板台面,定制镜柜，烤漆柜体，科勒陶瓷盆（按米收费）（德利丰大板可选）（不含龙头）
A15: 2 | C15: 钢架焊接 | E15: 米 | G15: 700 | H15: =F15*G15 -> 0 | I15: 1米以内（按米收费）
A18: 【顾朗龙头】
C19: 德国顾朗单柄面盆龙头 | E19: 个 | G19: 580 | H19: =F19*G19 -> 0 | I19: L-4386（HB/DB/NB/WB/JA/EB/QB/CA（高度在18cm左右）
C20: 德国顾朗单柄面盆龙头 | E20: 个 | G20: 580 | H20: =F20*G20 -> 0 | I20: L-4381（HB/DB/NB/WB/JA/EB/QB/CA（高度在18cm左右）
C21: 德国顾朗单柄面盆龙头 | E21: 个 | G21: 930 | H21: =F21*G21 -> 0 | I21: L4223/4221/4222/42882(高度在30cm左右)
C22: 德国顾朗浴缸龙头 | E22: 个 | G22: 2799 | H22: =F22*G22 -> 0 | I22: L-8579（HB/DB/NB/JA/EB/QB/CA/wb（高度在101cm左右）
C23: 德国顾朗悬吊龙头 | E23: 个 | G23: 2180 | H23: =F23*G23 -> 0 | I23: L-5433
C24: 德国顾朗喷枪龙头 | E24: 个 | G24: 300 | H24: =F24*G24 -> 0
C26: 德国顾朗暗装龙头 | E26: 个 | G26: 1380 | H26: =F26*G26 -> 0 | I26: L-4402（HB/DB/NB/WB/JA/EB/QB/CA（长度在18.2cm左右）
C27: 德国顾朗暗装龙头 | E27: 个 | G27: 1380 | H27: =F27*G27 -> 0 | I27: L-4426（HB/DB/NB/WB/JA/EB/QB/CA（长度在20cm左右）
C28: 德国顾朗暗装龙头 | E28: 个 | G28: 1380 | H28: =F28*G28 -> 0 | I28: L-4427（HB/DB/NB/WB/JA/EB/QB/CA（长度在20.8cm左右）
A32: 个性定制款 | C32: 德国顾朗暗装龙头 | E32: 个 | G32: 2099 | H32: =F32*G32 -> 0 | I32: L-4428（NB/EB/QB/CA（长度在20cm左右）
C33: 德国顾朗暗装龙头 | E33: 个 | G33: 2799 | H33: =F33*G33 -> 0 | I33: L-4417（NB/EB/QB/CA（长度在20cm左右）
A35: 【威博施水槽】
C37: 水槽 | E37: 个 | G37: 800 | H37: =F37*G37 -> 0 | I37: 威博施
C38: 拉篮、碗篮 | E38: 项 | G38: 800 | H38: =F38*G38 -> 0 | I38: 库博
C39: 厨房抽拉手头龙 | E39: 个 | G39: 688 | H39: =F39*G39 -> 0 | I39: 德国顾朗（L-6051/6050/6058CA/6058HB）
C40: 台下盆工艺 | E40: 项 | G40: 200 | H40: =F40*G40 -> 0 | I40: 安装
A42: 【顾朗花洒】
C43: 德国顾朗明装花洒 | E43: 个 | G43: 1600 | H43: =F43*G43 -> 0 | I43: L-8551/8550/8577CA/8577NB/8577HB
C44: 德国顾朗明装花洒 | E44: 个 | G44: 2280 | H44: =F44*G44 -> 0 | I44: L-8560（EB/QB/）8567/8580CA
C47: 德国顾朗暗装花洒 | E47: 个 | G47: 3200 | H47: =F47*G47 -> 0 | I47: L-8325/ NB / WB / CA / HB / EB/8345CA/8366CA
C48: 德国顾朗暗装花洒 | E48: 个 | G48: 4358 | H48: =F48*G48 -> 0 | I48: L-8325/ HB / WB / CA / HB / EB
C49: 德国顾朗暗装花洒 | E49: 个 | G49: 5700 | H49: =F49*G49 -> 0 | I49: L-8352/ JA/ QB / NB / HB
C50: 德国顾朗暗装花洒 | E50: 个 | G50: 7000 | H50: =F50*G50 -> 0 | I50: L-8367/ EB/ QB / NB / CA
A52: 【汉斯格雅花洒】
C53: 汉斯格雅明装花洒 | E53: 个 | G53: 4200 | H53: =F53*G53 -> 0 | I53: 2436007+24111007+26505007
...

Sheet 主材 岩板
A3: 【一、石材】
A4: 3 | C4: 人造石 | E4: 平方 | G4: 699 | H4: =F4*G4 -> 0 | I4: 1、人造飘窗石 2、定制石材面板（特殊花纹另算）。
A5: 4 | C5: 天然石 | E5: 平方 | G5: 1000 | H5: =F5*G5 -> 0 | I5: 1、人造飘窗石 2、定制石材面板（特殊花纹另算）。
A6: 5 | C6: 天然石 | E6: M | G6: 1300 | H6: =F6*G6 -> 0 | I6: 1、人造飘窗石 2、定制石材面板（特殊花纹另算）。
A7: 6 | C7: 玉石 | E7: M | G7: 2500 | H7: =F7*G7 -> 0 | I7: 1、人造飘窗石 2、定制石材面板（特殊花纹另算）。
A8: 【二、岩板】
A11: 1 | C11: 岩板定制 | E11: 片 | F11: 1 | G11: 2500 | H11: =F11*G11 -> 2500 | I11: 岩板规格1200*2700*9（包含按照加工）
A12: 2 | C12: 德利丰岩板定制 | E12: 片 | F12: 1 | G12: 4000 | H12: =F12*G12 -> 4000 | I12: 岩板规格1200*2700*9（包含按照加工）
A13: 3 | C13: 德利丰大板岛台定制 | E13: 米 | F13: 1 | G13: 1600 | H13: =F13*G13 -> 1600 | I13: 岩板规格1600*3200*12（包含按照加工）

Sheet 主材定制门
A2: 【一、定制门】
A4: 【铂屿定制玻璃移门】
A5: 1 | C5: 杜格平开门 | E5: 樘 | G5: 2200 | H5: =F5*G5 -> 0 | I5: 铂屿定制（杜格铝材、欧派克五金、40*13、2.5米以内）
A6: 1 | C6: 杜格法式平开门 | E6: 樘 | G6: 3000 | H6: =F6*G6 -> 0 | I6: 铂屿定制（杜格铝材、欧派克五金、40*13、2.5米以内）
A7: 1 | C7: 杜格隐框门 | E7: 樘 | G7: 3000 | H7: =F7*G7 -> 0 | I7: 铂屿定制（杜格铝材、欧派克五金、40*13、2.5米以内）
A8: 3 | C8: 40完美系统移门 | E8: 平方 | G8: 950 | I8: 铂屿定制（杜格铝材、欧派克五金、40*13完美系统、最大尺寸2700*900）
A9: 4 | C9: 45完美系统移门 | E9: 平方 | G9: 1150 | I9: 铂屿定制（杜格铝材、欧派克五金、40*16完美系统、最大尺寸3000*1200）
A10: 5 | C10: 特殊玻璃费用 | E10: 平方 | G10: 200 | H10: =F10*G10 -> 0 | I10: 特殊玻璃费用
A12: 5 | C12: 铝合金门套 | E12: M | G12: 200 | H12: =F12*G12 -> 0 | I12: 铝合金双包套
A13: 6 | C13: 木质门套 | E13: M | G13: 200 | H13: =F13*G13 -> 0 | I13: 木质包套
A14: 7 | C14: 不锈钢套 | E14: M2 | G14: 980 | H14: =F14*G14 -> 0 | I14: 304抗指纹不锈钢套5mm
A15: 法式移门增加200一平，双玻增加200一平
B20: 【铂屿定制玻璃平开门】
A21: 1 | C21: 涂料隐型门 | E21: 樘 | G21: 3500 | H21: =F21*G21 -> 0 | I21: 铂屿定制实木涂料隐框门（包含安装，门锁）（标高2.4米）
A22: 2 | C22: 玻璃隐框门 | E22: 樘 | G22: 4000 | H22: =F22*G22 -> 0 | I22: 铂屿定制40*13玻璃隐框门（包含安装，门锁）（标高2.4米）
A24: 6 | C24: 偏/中轴门 | E24: 平方 | G24: 1100 | I24: 铂屿定制40*13玻璃移门（包含安装，门锁）电机配件不含
A25: 7 | C25: 重型门 | E25: 平方 | G25: 1500 | I25: 铂屿定制玻璃移门（包含安装，门锁）不带阻尼
A26: 8 | C26: （格栅）玻璃门 | E26: 平方 | G26: 2000 | I26: 铂屿定制格栅玻璃（包含安装，门锁）opk五金

Sheet 其他主材 
A2: 【一、瓷砖】
A3: 【开关、插座面板】
A4: 1 | C4: 全屋开关插座面板 | E4: M2 | G4: 30 | H4: =F4*G4 -> 0 | I4: 施耐德珍铂系列（白色）
A5: 1 | C5: 全屋开关插座面板 | E5: M2 | G5: 35 | H5: =F5*G5 -> 0 | I5: 施耐德珍铂系列（黑色）
A6: 【集成吊顶】
A7: 1 | C7: 集成吊顶 | D7: 300*600 | E7: M2 | G7: 180 | H7: =F7*G7 -> 0 | I7: 本科铝扣板吊顶
A8: 2 | C8: 蜂窝大板 | E8: M2 | G8: 280 | H8: =F8*G8 -> 0 | I8: 本科蜂窝大板
A9: 3 | C9: 风暖 | D9: 300*600 | E9: 个 | G9: 499 | H9: =F9*G9 -> 0 | I9: 本科五合一风暖
A10: 4 | C10: 线型风暖 | E10: 个 | G10: 1280 | H10: =F10*G10 -> 0 | I10: 本科
A11: 【美缝】
A12: 1 | C12: 美缝 | E12: M2 | G12: 25 | H12: =F12*G12 -> 0 | I12: 梵聚匠（调色增加500元一个色）
A13: 2 | C13: 小砖环氧彩砂 | E13: M2 | G13: 180 | H13: =F13*G13 -> 0 | I13: 梵聚匠（10*100/100/200）压缝工艺（调色增加500元一个色）
A14: 3 | C14: 马贝环氧彩砂 | E14: M | G14: 20 | H14: =F14*G14 -> 0 | I14: 马贝环氧彩砂（平缝工艺）
A16: 【台面】
A17: 1 | C17: 石英石台面（单色/颗粒系列） | E17: M | G17: 499 | H17: =F17*G17 -> 0 | I17: 1、水泥砂浆辅料。 2、定制石材面板 3、厚度不超过1.5CM，宽度不大于70cm。(2.0c增加200一米)
A18: 2 | C18: 石英石台面（超白） | E18: M | G18: 699 | H18: =F18*G18 -> 0 | I18: 1、水泥砂浆辅料。 2、定制石材面板 3、厚度不超过1.5CM，宽度不大于70cm。(2.0c增加200一米)
A19: 3 | C19: 石英石台面（花纹） | E19: M | G19: 799 | H19: =F19*G19 -> 0 | I19: 1、水泥砂浆辅料。 2、定制石材面板 3、厚度不超过1.5CM，宽度不大于70cm。(2.0c增加200一米)
A20: 4 | C20: 石英石台面（鱼肚白/净黑系列） | E20: M | G20: 899 | H20: =F20*G20 -> 0 | I20: 1、水泥砂浆辅料。 2、定制石材面板 3、厚度不超过1.5CM，宽度不大于70cm。(2.0c增加200一米)
A21: 5 | C21: 德利丰岩板台面 | E21: M | G21: 1600 | H21: =F21*G21 -> 0 | I21: 1、水泥砂浆辅料。 2、定制石材面板 3、厚度不超过1.5CM，宽度不大于70cm。(2.0c增加200一米)
A22: 6 | C22: 赛凯隆石英石台面系列 | E22: M | G22: 1200 | H22: =F22*G22 -> 0 | I22: 产品标价5折
A23: 7 | C23: 不锈钢台面 | E23: M | G23: 1799 | H23: =F23*G23 -> 0 | I23: 304不锈钢5MM
A24: 【收口型材】
A25: 9 | C25: 收口型材 | E25: M | G25: 30 | H25: =F25*G25 -> 0 | I25: 铝合金型材预埋，界面剂涂刷，油漆收口
A26: 10 | C26: 阴影缝型材 | E26: M | G26: 30 | H26: =F26*G26 -> 0 | I26: 铝合金型材预埋，界面剂涂刷，油漆收口
A27: 11 | C27: 斜面灯槽型材 | E27: M | G27: 60 | H27: =F27*G27 -> 0 | I27: 铝合金型材预埋，界面剂涂刷，油漆收口
A28: 12 | C28: 平面脱缝型材 | E28: M | G28: 40 | H28: =F28*G28 -> 0 | I28: 铝合金型材预埋，界面剂涂刷，油漆收口
A30: 【艺术漆】
A31: 1 | C31: 曼德丽艺术漆 | E31: M2 | G31: 100 | H31: =F31*G31 -> 0 | I31: 天鹅绒/雅晶石
A32: 2 | C32: 嘉宝莉艺术漆 | E32: M2 | G32: 120 | H32: =F32*G32 -> 0 | I32: 天鹅绒/雅晶石
A33: 3 | C33: 佐敦北欧之家 | E33: M | G33: 110 | H33: =F33*G33 -> 0 | I33: 哑光（纯色）
A34: 4 | C34: 佐敦秘境 | E34: M | G34: 150 | H34: =F34*G34 -> 0 | I34: 哑光（纯色）
A35: 5 | C35: 佐敦之纯 | E35: M | G35: 170 | H35: =F35*G35 -> 0 | I35: 小羊皮（纯色）
A36: 6 | C36: 佐敦岩彩 | E36: M | G36: 200 | H36: =F36*G36 -> 0 | I36: 刀刮斑驳纹理
A38: 1 | C38: 不锈钢飘窗套 | E38: M2 | F38: 0 | G38: 880 | H38: =F38*G38 -> 0 | I38: 304不锈钢套
A39: 2 | C39: 不锈钢包梁 | E39: M2 | F39: 0 | G39: 480 | H39: =F39*G39 -> 0 | I39: 201不锈钢套
